return { { ["x"] = 0, ["meta"] = { ["fields"] = {  }, ["inventory"] = {  } }, ["param2"] = 0, ["y"] = 0, ["param1"] = 0, ["z"] = 12, ["name"] = "lottother:mordor_stone" }, { ["x"] = 0, ["meta"] = { ["fields"] = {  }, ["inventory"] = {  } }, ["param2"] = 0, ["y"] = 0, ["param1"] = 0, ["z"] = 13, ["name"] = "lottother:mordor_stone" }, { ["x"] = 0, ["meta"] = { ["fields"] = {  }, ["inventory"] = {  } }, ["param2"] = 0, ["y"] = 0, ["param1"] = 0, ["z"] = 14, ["name"] = "lottother:mordor_stone" }, { ["x"] = 0, ["meta"] = { ["fields"] = {  }, ["inventory"] = {  } }, ["param2"] = 0, ["y"] = 0, ["param1"] = 0, ["z"] = 15, ["name"] = "lottother:mordor_stone" }, { ["x"] = 0, ["meta"] = { ["fields"] = {  }, ["inventory"] = {  } }, ["param2"] = 0, ["y"] = 0, ["param1"] = 0, ["z"] = 16, ["name"] = "lottother:mordor_stone" }, { ["x"] = 1, ["meta"] = { ["fields"] = {  }, ["inventory"] = {  } }, ["param2"] = 0, ["y"] = 0, ["param1"] = 0, ["z"] = 11, ["name"] = "lottother:mordor_stone" }, { ["x"] = 1, ["meta"] = { ["fields"] = {  }, ["inventory"] = {  } }, ["param2"] = 0, ["y"] = 0, ["param1"] = 0, ["z"] = 12, ["name"] = "lottother:mordor_stone" }, { ["x"] = 1, ["meta"] = { ["fields"] = {  }, ["inventory"] = {  } }, ["param2"] = 0, ["y"] = 0, ["param1"] = 0, ["z"] = 13, ["name"] = "lottother:mordor_stone" }, { ["x"] = 1, ["meta"] = { ["fields"] = {  }, ["inventory"] = {  } }, ["param2"] = 0, ["y"] = 0, ["param1"] = 0, ["z"] = 14, ["name"] = "lottother:mordor_stone" }, { ["x"] = 1, ["meta"] = { ["fields"] = {  }, ["inventory"] = {  } }, ["param2"] = 0, ["y"] = 0, ["param1"] = 0, ["z"] = 15, ["name"] = "lottother:mordor_stone" }, { ["x"] = 1, ["meta"] = { ["fields"] = {  }, ["inventory"] = {  } }, ["param2"] = 0, ["y"] = 0, ["param1"] = 0, ["z"] = 16, ["name"] = "lottother:mordor_stone" }, { ["x"] = 1, ["meta"] = { ["fields"] = {  }, ["inventory"] = {  } }, ["param2"] = 0, ["y"] = 0, ["param1"] = 0, ["z"] = 17, ["name"] = "lottother:mordor_stone" }, { ["x"] = 1, ["meta"] = { ["fields"] = {  }, ["inventory"] = {  } }, ["param2"] = 0, ["y"] = 1, ["param1"] = 0, ["z"] = 13, ["name"] = "lottother:mordor_stone" }, { ["x"] = 1, ["meta"] = { ["fields"] = {  }, ["inventory"] = {  } }, ["param2"] = 0, ["y"] = 1, ["param1"] = 0, ["z"] = 14, ["name"] = "lottother:mordor_stone" }, { ["x"] = 1, ["meta"] = { ["fields"] = {  }, ["inventory"] = {  } }, ["param2"] = 0, ["y"] = 1, ["param1"] = 0, ["z"] = 15, ["name"] = "lottother:mordor_stone" }, { ["x"] = 2, ["meta"] = { ["fields"] = {  }, ["inventory"] = {  } }, ["param2"] = 0, ["y"] = 0, ["param1"] = 0, ["z"] = 10, ["name"] = "lottother:mordor_stone" }, { ["x"] = 2, ["meta"] = { ["fields"] = {  }, ["inventory"] = {  } }, ["param2"] = 0, ["y"] = 0, ["param1"] = 0, ["z"] = 11, ["name"] = "lottother:mordor_stone" }, { ["x"] = 2, ["meta"] = { ["fields"] = {  }, ["inventory"] = {  } }, ["param2"] = 0, ["y"] = 0, ["param1"] = 0, ["z"] = 12, ["name"] = "lottother:mordor_stone" }, { ["x"] = 2, ["meta"] = { ["fields"] = {  }, ["inventory"] = {  } }, ["param2"] = 0, ["y"] = 0, ["param1"] = 0, ["z"] = 13, ["name"] = "lottother:mordor_stone" }, { ["x"] = 2, ["meta"] = { ["fields"] = {  }, ["inventory"] = {  } }, ["param2"] = 0, ["y"] = 0, ["param1"] = 0, ["z"] = 14, ["name"] = "lottother:mordor_stone" }, { ["x"] = 2, ["meta"] = { ["fields"] = {  }, ["inventory"] = {  } }, ["param2"] = 0, ["y"] = 0, ["param1"] = 0, ["z"] = 15, ["name"] = "lottother:mordor_stone" }, { ["x"] = 2, ["meta"] = { ["fields"] = {  }, ["inventory"] = {  } }, ["param2"] = 0, ["y"] = 0, ["param1"] = 0, ["z"] = 16, ["name"] = "lottother:mordor_stone" }, { ["x"] = 2, ["meta"] = { ["fields"] = {  }, ["inventory"] = {  } }, ["param2"] = 0, ["y"] = 0, ["param1"] = 0, ["z"] = 17, ["name"] = "lottother:mordor_stone" }, { ["x"] = 2, ["meta"] = { ["fields"] = {  }, ["inventory"] = {  } }, ["param2"] = 0, ["y"] = 0, ["param1"] = 0, ["z"] = 18, ["name"] = "lottother:mordor_stone" }, { ["x"] = 2, ["meta"] = { ["fields"] = {  }, ["inventory"] = {  } }, ["param2"] = 0, ["y"] = 1, ["param1"] = 0, ["z"] = 12, ["name"] = "lottother:mordor_stone" }, { ["x"] = 2, ["meta"] = { ["fields"] = {  }, ["inventory"] = {  } }, ["param2"] = 0, ["y"] = 1, ["param1"] = 0, ["z"] = 13, ["name"] = "lottother:mordor_stone" }, { ["x"] = 2, ["meta"] = { ["fields"] = {  }, ["inventory"] = {  } }, ["param2"] = 0, ["y"] = 1, ["param1"] = 0, ["z"] = 14, ["name"] = "lottother:mordor_stone" }, { ["x"] = 2, ["meta"] = { ["fields"] = {  }, ["inventory"] = {  } }, ["param2"] = 0, ["y"] = 1, ["param1"] = 0, ["z"] = 15, ["name"] = "lottother:mordor_stone" }, { ["x"] = 2, ["meta"] = { ["fields"] = {  }, ["inventory"] = {  } }, ["param2"] = 0, ["y"] = 1, ["param1"] = 0, ["z"] = 16, ["name"] = "lottother:mordor_stone" }, { ["x"] = 2, ["meta"] = { ["fields"] = {  }, ["inventory"] = {  } }, ["param2"] = 0, ["y"] = 2, ["param1"] = 0, ["z"] = 14, ["name"] = "default:stone" }, { ["x"] = 3, ["meta"] = { ["fields"] = {  }, ["inventory"] = {  } }, ["param2"] = 0, ["y"] = 0, ["param1"] = 0, ["z"] = 9, ["name"] = "lottother:mordor_stone" }, { ["x"] = 3, ["meta"] = { ["fields"] = {  }, ["inventory"] = {  } }, ["param2"] = 0, ["y"] = 0, ["param1"] = 0, ["z"] = 10, ["name"] = "lottother:mordor_stone" }, { ["x"] = 3, ["meta"] = { ["fields"] = {  }, ["inventory"] = {  } }, ["param2"] = 0, ["y"] = 0, ["param1"] = 0, ["z"] = 11, ["name"] = "lottother:mordor_stone" }, { ["x"] = 3, ["meta"] = { ["fields"] = {  }, ["inventory"] = {  } }, ["param2"] = 0, ["y"] = 0, ["param1"] = 0, ["z"] = 12, ["name"] = "lottother:mordor_stone" }, { ["x"] = 3, ["meta"] = { ["fields"] = {  }, ["inventory"] = {  } }, ["param2"] = 0, ["y"] = 0, ["param1"] = 0, ["z"] = 13, ["name"] = "lottother:mordor_stone" }, { ["x"] = 3, ["meta"] = { ["fields"] = {  }, ["inventory"] = {  } }, ["param2"] = 0, ["y"] = 0, ["param1"] = 0, ["z"] = 14, ["name"] = "lottother:mordor_stone" }, { ["x"] = 3, ["meta"] = { ["fields"] = {  }, ["inventory"] = {  } }, ["param2"] = 0, ["y"] = 0, ["param1"] = 0, ["z"] = 15, ["name"] = "lottother:mordor_stone" }, { ["x"] = 3, ["meta"] = { ["fields"] = {  }, ["inventory"] = {  } }, ["param2"] = 0, ["y"] = 0, ["param1"] = 0, ["z"] = 16, ["name"] = "lottother:mordor_stone" }, { ["x"] = 3, ["meta"] = { ["fields"] = {  }, ["inventory"] = {  } }, ["param2"] = 0, ["y"] = 0, ["param1"] = 0, ["z"] = 17, ["name"] = "lottother:mordor_stone" }, { ["x"] = 3, ["meta"] = { ["fields"] = {  }, ["inventory"] = {  } }, ["param2"] = 0, ["y"] = 0, ["param1"] = 0, ["z"] = 18, ["name"] = "lottother:mordor_stone" }, { ["x"] = 3, ["meta"] = { ["fields"] = {  }, ["inventory"] = {  } }, ["param2"] = 0, ["y"] = 0, ["param1"] = 0, ["z"] = 19, ["name"] = "lottother:mordor_stone" }, { ["x"] = 3, ["meta"] = { ["fields"] = {  }, ["inventory"] = {  } }, ["param2"] = 0, ["y"] = 1, ["param1"] = 0, ["z"] = 11, ["name"] = "lottother:mordor_stone" }, { ["x"] = 3, ["meta"] = { ["fields"] = {  }, ["inventory"] = {  } }, ["param2"] = 0, ["y"] = 1, ["param1"] = 0, ["z"] = 12, ["name"] = "lottother:mordor_stone" }, { ["x"] = 3, ["meta"] = { ["fields"] = {  }, ["inventory"] = {  } }, ["param2"] = 0, ["y"] = 1, ["param1"] = 0, ["z"] = 13, ["name"] = "lottother:mordor_stone" }, { ["x"] = 3, ["meta"] = { ["fields"] = {  }, ["inventory"] = {  } }, ["param2"] = 0, ["y"] = 1, ["param1"] = 0, ["z"] = 14, ["name"] = "lottother:mordor_stone" }, { ["x"] = 3, ["meta"] = { ["fields"] = {  }, ["inventory"] = {  } }, ["param2"] = 0, ["y"] = 1, ["param1"] = 0, ["z"] = 15, ["name"] = "lottother:mordor_stone" }, { ["x"] = 3, ["meta"] = { ["fields"] = {  }, ["inventory"] = {  } }, ["param2"] = 0, ["y"] = 1, ["param1"] = 0, ["z"] = 16, ["name"] = "lottother:mordor_stone" }, { ["x"] = 3, ["meta"] = { ["fields"] = {  }, ["inventory"] = {  } }, ["param2"] = 0, ["y"] = 1, ["param1"] = 0, ["z"] = 17, ["name"] = "lottother:mordor_stone" }, { ["x"] = 3, ["meta"] = { ["fields"] = {  }, ["inventory"] = {  } }, ["param2"] = 0, ["y"] = 2, ["param1"] = 0, ["z"] = 13, ["name"] = "default:stone" }, { ["x"] = 3, ["meta"] = { ["fields"] = {  }, ["inventory"] = {  } }, ["param2"] = 0, ["y"] = 2, ["param1"] = 0, ["z"] = 14, ["name"] = "default:stone" }, { ["x"] = 3, ["meta"] = { ["fields"] = {  }, ["inventory"] = {  } }, ["param2"] = 0, ["y"] = 2, ["param1"] = 0, ["z"] = 15, ["name"] = "default:stone" }, { ["x"] = 3, ["meta"] = { ["fields"] = {  }, ["inventory"] = {  } }, ["param2"] = 0, ["y"] = 3, ["param1"] = 0, ["z"] = 13, ["name"] = "default:stone" }, { ["x"] = 3, ["meta"] = { ["fields"] = {  }, ["inventory"] = {  } }, ["param2"] = 0, ["y"] = 3, ["param1"] = 0, ["z"] = 14, ["name"] = "default:stone" }, { ["x"] = 3, ["meta"] = { ["fields"] = {  }, ["inventory"] = {  } }, ["param2"] = 0, ["y"] = 3, ["param1"] = 0, ["z"] = 15, ["name"] = "default:stone" }, { ["x"] = 3, ["meta"] = { ["fields"] = {  }, ["inventory"] = {  } }, ["param2"] = 0, ["y"] = 4, ["param1"] = 0, ["z"] = 14, ["name"] = "default:stone" }, { ["x"] = 4, ["meta"] = { ["fields"] = {  }, ["inventory"] = {  } }, ["param2"] = 0, ["y"] = 0, ["param1"] = 0, ["z"] = 7, ["name"] = "lottother:mordor_stone" }, { ["x"] = 4, ["meta"] = { ["fields"] = {  }, ["inventory"] = {  } }, ["param2"] = 0, ["y"] = 0, ["param1"] = 0, ["z"] = 8, ["name"] = "lottother:mordor_stone" }, { ["x"] = 4, ["meta"] = { ["fields"] = {  }, ["inventory"] = {  } }, ["param2"] = 0, ["y"] = 0, ["param1"] = 0, ["z"] = 9, ["name"] = "lottother:mordor_stone" }, { ["x"] = 4, ["meta"] = { ["fields"] = {  }, ["inventory"] = {  } }, ["param2"] = 0, ["y"] = 0, ["param1"] = 13, ["z"] = 10, ["name"] = "lottother:mordor_stone" }, { ["x"] = 4, ["meta"] = { ["fields"] = {  }, ["inventory"] = {  } }, ["param2"] = 0, ["y"] = 0, ["param1"] = 13, ["z"] = 11, ["name"] = "lottother:mordor_stone" }, { ["x"] = 4, ["meta"] = { ["fields"] = {  }, ["inventory"] = {  } }, ["param2"] = 0, ["y"] = 0, ["param1"] = 13, ["z"] = 12, ["name"] = "lottother:mordor_stone" }, { ["x"] = 4, ["meta"] = { ["fields"] = {  }, ["inventory"] = {  } }, ["param2"] = 0, ["y"] = 0, ["param1"] = 12, ["z"] = 13, ["name"] = "lottother:mordor_stone" }, { ["x"] = 4, ["meta"] = { ["fields"] = {  }, ["inventory"] = {  } }, ["param2"] = 0, ["y"] = 0, ["param1"] = 11, ["z"] = 14, ["name"] = "lottother:mordor_stone" }, { ["x"] = 4, ["meta"] = { ["fields"] = {  }, ["inventory"] = {  } }, ["param2"] = 0, ["y"] = 0, ["param1"] = 12, ["z"] = 15, ["name"] = "lottother:mordor_stone" }, { ["x"] = 4, ["meta"] = { ["fields"] = {  }, ["inventory"] = {  } }, ["param2"] = 0, ["y"] = 0, ["param1"] = 13, ["z"] = 16, ["name"] = "lottother:mordor_stone" }, { ["x"] = 4, ["meta"] = { ["fields"] = {  }, ["inventory"] = {  } }, ["param2"] = 0, ["y"] = 0, ["param1"] = 13, ["z"] = 17, ["name"] = "lottother:mordor_stone" }, { ["x"] = 4, ["meta"] = { ["fields"] = {  }, ["inventory"] = {  } }, ["param2"] = 0, ["y"] = 0, ["param1"] = 13, ["z"] = 18, ["name"] = "lottother:mordor_stone" }, { ["x"] = 4, ["meta"] = { ["fields"] = {  }, ["inventory"] = {  } }, ["param2"] = 0, ["y"] = 0, ["param1"] = 0, ["z"] = 19, ["name"] = "lottother:mordor_stone" }, { ["x"] = 4, ["meta"] = { ["fields"] = {  }, ["inventory"] = {  } }, ["param2"] = 0, ["y"] = 0, ["param1"] = 0, ["z"] = 20, ["name"] = "lottother:mordor_stone" }, { ["x"] = 4, ["meta"] = { ["fields"] = {  }, ["inventory"] = {  } }, ["param2"] = 0, ["y"] = 0, ["param1"] = 0, ["z"] = 21, ["name"] = "lottother:mordor_stone" }, { ["x"] = 4, ["meta"] = { ["fields"] = {  }, ["inventory"] = {  } }, ["param2"] = 0, ["y"] = 1, ["param1"] = 13, ["z"] = 10, ["name"] = "lottother:mordor_stone" }, { ["x"] = 4, ["meta"] = { ["fields"] = {  }, ["inventory"] = {  } }, ["param2"] = 0, ["y"] = 1, ["param1"] = 13, ["z"] = 11, ["name"] = "lottother:mordor_stone" }, { ["x"] = 4, ["meta"] = { ["fields"] = {  }, ["inventory"] = {  } }, ["param2"] = 0, ["y"] = 1, ["param1"] = 13, ["z"] = 12, ["name"] = "lottother:mordor_stone" }, { ["x"] = 4, ["meta"] = { ["fields"] = {  }, ["inventory"] = {  } }, ["param2"] = 0, ["y"] = 1, ["param1"] = 12, ["z"] = 13, ["name"] = "lottother:mordor_stone" }, { ["x"] = 4, ["meta"] = { ["fields"] = {  }, ["inventory"] = {  } }, ["param2"] = 0, ["y"] = 1, ["param1"] = 11, ["z"] = 14, ["name"] = "lottother:mordor_stone" }, { ["x"] = 4, ["meta"] = { ["fields"] = {  }, ["inventory"] = {  } }, ["param2"] = 0, ["y"] = 1, ["param1"] = 12, ["z"] = 15, ["name"] = "lottother:mordor_stone" }, { ["x"] = 4, ["meta"] = { ["fields"] = {  }, ["inventory"] = {  } }, ["param2"] = 0, ["y"] = 1, ["param1"] = 13, ["z"] = 16, ["name"] = "lottother:mordor_stone" }, { ["x"] = 4, ["meta"] = { ["fields"] = {  }, ["inventory"] = {  } }, ["param2"] = 0, ["y"] = 1, ["param1"] = 13, ["z"] = 17, ["name"] = "lottother:mordor_stone" }, { ["x"] = 4, ["meta"] = { ["fields"] = {  }, ["inventory"] = {  } }, ["param2"] = 0, ["y"] = 1, ["param1"] = 13, ["z"] = 18, ["name"] = "lottother:mordor_stone" }, { ["x"] = 4, ["meta"] = { ["fields"] = {  }, ["inventory"] = {  } }, ["param2"] = 0, ["y"] = 2, ["param1"] = 0, ["z"] = 12, ["name"] = "default:stone" }, { ["x"] = 4, ["meta"] = { ["fields"] = {  }, ["inventory"] = {  } }, ["param2"] = 0, ["y"] = 2, ["param1"] = 0, ["z"] = 13, ["name"] = "default:stone" }, { ["x"] = 4, ["meta"] = { ["fields"] = {  }, ["inventory"] = {  } }, ["param2"] = 0, ["y"] = 2, ["param1"] = 0, ["z"] = 14, ["name"] = "default:stone" }, { ["x"] = 4, ["meta"] = { ["fields"] = {  }, ["inventory"] = {  } }, ["param2"] = 0, ["y"] = 2, ["param1"] = 0, ["z"] = 15, ["name"] = "default:stone" }, { ["x"] = 4, ["meta"] = { ["fields"] = {  }, ["inventory"] = {  } }, ["param2"] = 0, ["y"] = 2, ["param1"] = 0, ["z"] = 16, ["name"] = "default:stone" }, { ["x"] = 4, ["meta"] = { ["fields"] = {  }, ["inventory"] = {  } }, ["param2"] = 0, ["y"] = 3, ["param1"] = 0, ["z"] = 13, ["name"] = "default:stone" }, { ["x"] = 4, ["meta"] = { ["fields"] = {  }, ["inventory"] = {  } }, ["param2"] = 0, ["y"] = 3, ["param1"] = 0, ["z"] = 14, ["name"] = "default:stone" }, { ["x"] = 4, ["meta"] = { ["fields"] = {  }, ["inventory"] = {  } }, ["param2"] = 0, ["y"] = 3, ["param1"] = 0, ["z"] = 15, ["name"] = "default:stone" }, { ["x"] = 4, ["meta"] = { ["fields"] = {  }, ["inventory"] = {  } }, ["param2"] = 0, ["y"] = 4, ["param1"] = 0, ["z"] = 13, ["name"] = "default:stone" }, { ["x"] = 4, ["meta"] = { ["fields"] = {  }, ["inventory"] = {  } }, ["param2"] = 0, ["y"] = 4, ["param1"] = 0, ["z"] = 14, ["name"] = "default:stone" }, { ["x"] = 4, ["meta"] = { ["fields"] = {  }, ["inventory"] = {  } }, ["param2"] = 0, ["y"] = 4, ["param1"] = 0, ["z"] = 15, ["name"] = "default:stone" }, { ["x"] = 4, ["meta"] = { ["fields"] = {  }, ["inventory"] = {  } }, ["param2"] = 0, ["y"] = 5, ["param1"] = 0, ["z"] = 14, ["name"] = "default:stone" }, { ["x"] = 4, ["meta"] = { ["fields"] = {  }, ["inventory"] = {  } }, ["param2"] = 0, ["y"] = 6, ["param1"] = 0, ["z"] = 14, ["name"] = "default:stone" }, { ["x"] = 4, ["meta"] = { ["fields"] = {  }, ["inventory"] = {  } }, ["param2"] = 18, ["y"] = 11, ["param1"] = 0, ["z"] = 11, ["name"] = "default:tree" }, { ["x"] = 4, ["meta"] = { ["fields"] = {  }, ["inventory"] = {  } }, ["param2"] = 18, ["y"] = 11, ["param1"] = 0, ["z"] = 13, ["name"] = "default:tree" }, { ["x"] = 4, ["meta"] = { ["fields"] = {  }, ["inventory"] = {  } }, ["param2"] = 18, ["y"] = 11, ["param1"] = 0, ["z"] = 15, ["name"] = "default:tree" }, { ["x"] = 4, ["meta"] = { ["fields"] = {  }, ["inventory"] = {  } }, ["param2"] = 18, ["y"] = 11, ["param1"] = 0, ["z"] = 17, ["name"] = "default:tree" }, { ["x"] = 4, ["meta"] = { ["fields"] = {  }, ["inventory"] = {  } }, ["param2"] = 0, ["y"] = 12, ["param1"] = 0, ["z"] = 10, ["name"] = "lottmapgen:mordor_stone" }, { ["x"] = 4, ["meta"] = { ["fields"] = {  }, ["inventory"] = {  } }, ["param2"] = 0, ["y"] = 12, ["param1"] = 0, ["z"] = 11, ["name"] = "lottmapgen:mordor_stone" }, { ["x"] = 4, ["meta"] = { ["fields"] = {  }, ["inventory"] = {  } }, ["param2"] = 0, ["y"] = 12, ["param1"] = 0, ["z"] = 13, ["name"] = "lottmapgen:mordor_stone" }, { ["x"] = 4, ["meta"] = { ["fields"] = {  }, ["inventory"] = {  } }, ["param2"] = 0, ["y"] = 12, ["param1"] = 0, ["z"] = 14, ["name"] = "lottmapgen:mordor_stone" }, { ["x"] = 4, ["meta"] = { ["fields"] = {  }, ["inventory"] = {  } }, ["param2"] = 0, ["y"] = 12, ["param1"] = 0, ["z"] = 15, ["name"] = "lottmapgen:mordor_stone" }, { ["x"] = 4, ["meta"] = { ["fields"] = {  }, ["inventory"] = {  } }, ["param2"] = 0, ["y"] = 12, ["param1"] = 0, ["z"] = 17, ["name"] = "lottmapgen:mordor_stone" }, { ["x"] = 4, ["meta"] = { ["fields"] = {  }, ["inventory"] = {  } }, ["param2"] = 0, ["y"] = 12, ["param1"] = 0, ["z"] = 18, ["name"] = "lottmapgen:mordor_stone" }, { ["x"] = 4, ["meta"] = { ["fields"] = {  }, ["inventory"] = {  } }, ["param2"] = 0, ["y"] = 13, ["param1"] = 0, ["z"] = 10, ["name"] = "lottmapgen:mordor_stone" }, { ["x"] = 4, ["meta"] = { ["fields"] = {  }, ["inventory"] = {  } }, ["param2"] = 0, ["y"] = 13, ["param1"] = 0, ["z"] = 11, ["name"] = "lottmapgen:mordor_stone" }, { ["x"] = 4, ["meta"] = { ["fields"] = {  }, ["inventory"] = {  } }, ["param2"] = 0, ["y"] = 13, ["param1"] = 0, ["z"] = 12, ["name"] = "lottmapgen:mordor_stone" }, { ["x"] = 4, ["meta"] = { ["fields"] = {  }, ["inventory"] = {  } }, ["param2"] = 0, ["y"] = 13, ["param1"] = 0, ["z"] = 13, ["name"] = "lottmapgen:mordor_stone" }, { ["x"] = 4, ["meta"] = { ["fields"] = {  }, ["inventory"] = {  } }, ["param2"] = 0, ["y"] = 13, ["param1"] = 0, ["z"] = 14, ["name"] = "lottmapgen:mordor_stone" }, { ["x"] = 4, ["meta"] = { ["fields"] = {  }, ["inventory"] = {  } }, ["param2"] = 0, ["y"] = 13, ["param1"] = 0, ["z"] = 15, ["name"] = "lottmapgen:mordor_stone" }, { ["x"] = 4, ["meta"] = { ["fields"] = {  }, ["inventory"] = {  } }, ["param2"] = 0, ["y"] = 13, ["param1"] = 0, ["z"] = 16, ["name"] = "lottmapgen:mordor_stone" }, { ["x"] = 4, ["meta"] = { ["fields"] = {  }, ["inventory"] = {  } }, ["param2"] = 0, ["y"] = 13, ["param1"] = 0, ["z"] = 17, ["name"] = "lottmapgen:mordor_stone" }, { ["x"] = 4, ["meta"] = { ["fields"] = {  }, ["inventory"] = {  } }, ["param2"] = 0, ["y"] = 13, ["param1"] = 0, ["z"] = 18, ["name"] = "lottmapgen:mordor_stone" }, { ["x"] = 4, ["meta"] = { ["fields"] = {  }, ["inventory"] = {  } }, ["param2"] = 0, ["y"] = 14, ["param1"] = 0, ["z"] = 10, ["name"] = "lottmapgen:mordor_stone" }, { ["x"] = 4, ["meta"] = { ["fields"] = {  }, ["inventory"] = {  } }, ["param2"] = 0, ["y"] = 14, ["param1"] = 0, ["z"] = 11, ["name"] = "lottmapgen:mordor_stone" }, { ["x"] = 4, ["meta"] = { ["fields"] = {  }, ["inventory"] = {  } }, ["param2"] = 0, ["y"] = 14, ["param1"] = 15, ["z"] = 12, ["name"] = "lottother:air" }, { ["x"] = 4, ["meta"] = { ["fields"] = {  }, ["inventory"] = {  } }, ["param2"] = 0, ["y"] = 14, ["param1"] = 0, ["z"] = 13, ["name"] = "lottmapgen:mordor_stone" }, { ["x"] = 4, ["meta"] = { ["fields"] = {  }, ["inventory"] = {  } }, ["param2"] = 0, ["y"] = 14, ["param1"] = 0, ["z"] = 14, ["name"] = "lottmapgen:mordor_stone" }, { ["x"] = 4, ["meta"] = { ["fields"] = {  }, ["inventory"] = {  } }, ["param2"] = 0, ["y"] = 14, ["param1"] = 0, ["z"] = 15, ["name"] = "lottmapgen:mordor_stone" }, { ["x"] = 4, ["meta"] = { ["fields"] = {  }, ["inventory"] = {  } }, ["param2"] = 0, ["y"] = 14, ["param1"] = 15, ["z"] = 16, ["name"] = "lottother:air" }, { ["x"] = 4, ["meta"] = { ["fields"] = {  }, ["inventory"] = {  } }, ["param2"] = 0, ["y"] = 14, ["param1"] = 0, ["z"] = 17, ["name"] = "lottmapgen:mordor_stone" }, { ["x"] = 4, ["meta"] = { ["fields"] = {  }, ["inventory"] = {  } }, ["param2"] = 0, ["y"] = 14, ["param1"] = 0, ["z"] = 18, ["name"] = "lottmapgen:mordor_stone" }, { ["x"] = 4, ["meta"] = { ["fields"] = {  }, ["inventory"] = {  } }, ["param2"] = 0, ["y"] = 15, ["param1"] = 0, ["z"] = 10, ["name"] = "lottmapgen:mordor_stone" }, { ["x"] = 4, ["meta"] = { ["fields"] = {  }, ["inventory"] = {  } }, ["param2"] = 0, ["y"] = 15, ["param1"] = 0, ["z"] = 11, ["name"] = "lottmapgen:mordor_stone" }, { ["x"] = 4, ["meta"] = { ["fields"] = {  }, ["inventory"] = {  } }, ["param2"] = 0, ["y"] = 15, ["param1"] = 31, ["z"] = 12, ["name"] = "lottother:air" }, { ["x"] = 4, ["meta"] = { ["fields"] = {  }, ["inventory"] = {  } }, ["param2"] = 0, ["y"] = 15, ["param1"] = 0, ["z"] = 13, ["name"] = "lottmapgen:mordor_stone" }, { ["x"] = 4, ["meta"] = { ["fields"] = {  }, ["inventory"] = {  } }, ["param2"] = 0, ["y"] = 15, ["param1"] = 0, ["z"] = 14, ["name"] = "lottmapgen:mordor_stone" }, { ["x"] = 4, ["meta"] = { ["fields"] = {  }, ["inventory"] = {  } }, ["param2"] = 0, ["y"] = 15, ["param1"] = 0, ["z"] = 15, ["name"] = "lottmapgen:mordor_stone" }, { ["x"] = 4, ["meta"] = { ["fields"] = {  }, ["inventory"] = {  } }, ["param2"] = 0, ["y"] = 15, ["param1"] = 31, ["z"] = 16, ["name"] = "lottother:air" }, { ["x"] = 4, ["meta"] = { ["fields"] = {  }, ["inventory"] = {  } }, ["param2"] = 0, ["y"] = 15, ["param1"] = 0, ["z"] = 17, ["name"] = "lottmapgen:mordor_stone" }, { ["x"] = 4, ["meta"] = { ["fields"] = {  }, ["inventory"] = {  } }, ["param2"] = 0, ["y"] = 15, ["param1"] = 0, ["z"] = 18, ["name"] = "lottmapgen:mordor_stone" }, { ["x"] = 5, ["meta"] = { ["fields"] = {  }, ["inventory"] = {  } }, ["param2"] = 0, ["y"] = 0, ["param1"] = 0, ["z"] = 6, ["name"] = "lottother:mordor_stone" }, { ["x"] = 5, ["meta"] = { ["fields"] = {  }, ["inventory"] = {  } }, ["param2"] = 0, ["y"] = 0, ["param1"] = 0, ["z"] = 7, ["name"] = "lottother:mordor_stone" }, { ["x"] = 5, ["meta"] = { ["fields"] = {  }, ["inventory"] = {  } }, ["param2"] = 0, ["y"] = 0, ["param1"] = 15, ["z"] = 8, ["name"] = "lottother:mordor_stone" }, { ["x"] = 5, ["meta"] = { ["fields"] = {  }, ["inventory"] = {  } }, ["param2"] = 0, ["y"] = 0, ["param1"] = 13, ["z"] = 9, ["name"] = "lottother:mordor_stone" }, { ["x"] = 5, ["meta"] = { ["fields"] = {  }, ["inventory"] = {  } }, ["param2"] = 0, ["y"] = 0, ["param1"] = 12, ["z"] = 10, ["name"] = "lottother:mordor_stone" }, { ["x"] = 5, ["meta"] = { ["fields"] = {  }, ["inventory"] = {  } }, ["param2"] = 0, ["y"] = 0, ["param1"] = 12, ["z"] = 11, ["name"] = "lottother:mordor_stone" }, { ["x"] = 5, ["meta"] = { ["fields"] = {  }, ["inventory"] = {  } }, ["param2"] = 0, ["y"] = 0, ["param1"] = 12, ["z"] = 12, ["name"] = "lottother:mordor_stone" }, { ["x"] = 5, ["meta"] = { ["fields"] = {  }, ["inventory"] = {  } }, ["param2"] = 0, ["y"] = 0, ["param1"] = 11, ["z"] = 13, ["name"] = "lottother:mordor_stone" }, { ["x"] = 5, ["meta"] = { ["fields"] = {  }, ["inventory"] = {  } }, ["param2"] = 0, ["y"] = 0, ["param1"] = 10, ["z"] = 14, ["name"] = "lottother:mordor_stone" }, { ["x"] = 5, ["meta"] = { ["fields"] = {  }, ["inventory"] = {  } }, ["param2"] = 0, ["y"] = 0, ["param1"] = 11, ["z"] = 15, ["name"] = "lottother:mordor_stone" }, { ["x"] = 5, ["meta"] = { ["fields"] = {  }, ["inventory"] = {  } }, ["param2"] = 0, ["y"] = 0, ["param1"] = 12, ["z"] = 16, ["name"] = "lottother:mordor_stone" }, { ["x"] = 5, ["meta"] = { ["fields"] = {  }, ["inventory"] = {  } }, ["param2"] = 0, ["y"] = 0, ["param1"] = 12, ["z"] = 17, ["name"] = "lottother:mordor_stone" }, { ["x"] = 5, ["meta"] = { ["fields"] = {  }, ["inventory"] = {  } }, ["param2"] = 0, ["y"] = 0, ["param1"] = 12, ["z"] = 18, ["name"] = "lottother:mordor_stone" }, { ["x"] = 5, ["meta"] = { ["fields"] = {  }, ["inventory"] = {  } }, ["param2"] = 0, ["y"] = 0, ["param1"] = 13, ["z"] = 19, ["name"] = "lottother:mordor_stone" }, { ["x"] = 5, ["meta"] = { ["fields"] = {  }, ["inventory"] = {  } }, ["param2"] = 0, ["y"] = 0, ["param1"] = 15, ["z"] = 20, ["name"] = "lottother:mordor_stone" }, { ["x"] = 5, ["meta"] = { ["fields"] = {  }, ["inventory"] = {  } }, ["param2"] = 0, ["y"] = 0, ["param1"] = 0, ["z"] = 21, ["name"] = "lottother:mordor_stone" }, { ["x"] = 5, ["meta"] = { ["fields"] = {  }, ["inventory"] = {  } }, ["param2"] = 0, ["y"] = 0, ["param1"] = 0, ["z"] = 22, ["name"] = "lottother:mordor_stone" }, { ["x"] = 5, ["meta"] = { ["fields"] = {  }, ["inventory"] = {  } }, ["param2"] = 0, ["y"] = 1, ["param1"] = 15, ["z"] = 8, ["name"] = "lottother:mordor_stone" }, { ["x"] = 5, ["meta"] = { ["fields"] = {  }, ["inventory"] = {  } }, ["param2"] = 0, ["y"] = 1, ["param1"] = 13, ["z"] = 9, ["name"] = "lottother:mordor_stone" }, { ["x"] = 5, ["meta"] = { ["fields"] = {  }, ["inventory"] = {  } }, ["param2"] = 0, ["y"] = 1, ["param1"] = 12, ["z"] = 10, ["name"] = "lottother:mordor_stone" }, { ["x"] = 5, ["meta"] = { ["fields"] = {  }, ["inventory"] = {  } }, ["param2"] = 0, ["y"] = 1, ["param1"] = 12, ["z"] = 11, ["name"] = "lottother:mordor_stone" }, { ["x"] = 5, ["meta"] = { ["fields"] = {  }, ["inventory"] = {  } }, ["param2"] = 0, ["y"] = 1, ["param1"] = 12, ["z"] = 12, ["name"] = "lottother:mordor_stone" }, { ["x"] = 5, ["meta"] = { ["fields"] = {  }, ["inventory"] = {  } }, ["param2"] = 0, ["y"] = 1, ["param1"] = 11, ["z"] = 13, ["name"] = "lottother:mordor_stone" }, { ["x"] = 5, ["meta"] = { ["fields"] = {  }, ["inventory"] = {  } }, ["param2"] = 0, ["y"] = 1, ["param1"] = 10, ["z"] = 14, ["name"] = "lottother:mordor_stone" }, { ["x"] = 5, ["meta"] = { ["fields"] = {  }, ["inventory"] = {  } }, ["param2"] = 0, ["y"] = 1, ["param1"] = 11, ["z"] = 15, ["name"] = "lottother:mordor_stone" }, { ["x"] = 5, ["meta"] = { ["fields"] = {  }, ["inventory"] = {  } }, ["param2"] = 0, ["y"] = 1, ["param1"] = 12, ["z"] = 16, ["name"] = "lottother:mordor_stone" }, { ["x"] = 5, ["meta"] = { ["fields"] = {  }, ["inventory"] = {  } }, ["param2"] = 0, ["y"] = 1, ["param1"] = 12, ["z"] = 17, ["name"] = "lottother:mordor_stone" }, { ["x"] = 5, ["meta"] = { ["fields"] = {  }, ["inventory"] = {  } }, ["param2"] = 0, ["y"] = 1, ["param1"] = 12, ["z"] = 18, ["name"] = "lottother:mordor_stone" }, { ["x"] = 5, ["meta"] = { ["fields"] = {  }, ["inventory"] = {  } }, ["param2"] = 0, ["y"] = 1, ["param1"] = 13, ["z"] = 19, ["name"] = "lottother:mordor_stone" }, { ["x"] = 5, ["meta"] = { ["fields"] = {  }, ["inventory"] = {  } }, ["param2"] = 0, ["y"] = 1, ["param1"] = 0, ["z"] = 20, ["name"] = "lottother:mordor_stone" }, { ["x"] = 5, ["meta"] = { ["fields"] = {  }, ["inventory"] = {  } }, ["param2"] = 0, ["y"] = 2, ["param1"] = 0, ["z"] = 11, ["name"] = "lottmapgen:mordor_stone" }, { ["x"] = 5, ["meta"] = { ["fields"] = {  }, ["inventory"] = {  } }, ["param2"] = 0, ["y"] = 2, ["param1"] = 0, ["z"] = 12, ["name"] = "lottmapgen:mordor_stone" }, { ["x"] = 5, ["meta"] = { ["fields"] = {  }, ["inventory"] = {  } }, ["param2"] = 0, ["y"] = 2, ["param1"] = 0, ["z"] = 13, ["name"] = "lottmapgen:mordor_stone" }, { ["x"] = 5, ["meta"] = { ["fields"] = {  }, ["inventory"] = {  } }, ["param2"] = 0, ["y"] = 2, ["param1"] = 0, ["z"] = 14, ["name"] = "lottmapgen:mordor_stone" }, { ["x"] = 5, ["meta"] = { ["fields"] = {  }, ["inventory"] = {  } }, ["param2"] = 0, ["y"] = 2, ["param1"] = 0, ["z"] = 15, ["name"] = "lottmapgen:mordor_stone" }, { ["x"] = 5, ["meta"] = { ["fields"] = {  }, ["inventory"] = {  } }, ["param2"] = 0, ["y"] = 2, ["param1"] = 0, ["z"] = 16, ["name"] = "lottmapgen:mordor_stone" }, { ["x"] = 5, ["meta"] = { ["fields"] = {  }, ["inventory"] = {  } }, ["param2"] = 0, ["y"] = 2, ["param1"] = 0, ["z"] = 17, ["name"] = "lottmapgen:mordor_stone" }, { ["x"] = 5, ["meta"] = { ["fields"] = {  }, ["inventory"] = {  } }, ["param2"] = 0, ["y"] = 3, ["param1"] = 0, ["z"] = 11, ["name"] = "lottmapgen:mordor_stone" }, { ["x"] = 5, ["meta"] = { ["fields"] = {  }, ["inventory"] = {  } }, ["param2"] = 0, ["y"] = 3, ["param1"] = 0, ["z"] = 12, ["name"] = "lottmapgen:mordor_stone" }, { ["x"] = 5, ["meta"] = { ["fields"] = {  }, ["inventory"] = {  } }, ["param2"] = 0, ["y"] = 3, ["param1"] = 0, ["z"] = 13, ["name"] = "lottmapgen:mordor_stone" }, { ["x"] = 5, ["meta"] = { ["fields"] = {  }, ["inventory"] = {  } }, ["param2"] = 0, ["y"] = 3, ["param1"] = 0, ["z"] = 14, ["name"] = "lottmapgen:mordor_stone" }, { ["x"] = 5, ["meta"] = { ["fields"] = {  }, ["inventory"] = {  } }, ["param2"] = 0, ["y"] = 3, ["param1"] = 0, ["z"] = 15, ["name"] = "lottmapgen:mordor_stone" }, { ["x"] = 5, ["meta"] = { ["fields"] = {  }, ["inventory"] = {  } }, ["param2"] = 0, ["y"] = 3, ["param1"] = 0, ["z"] = 16, ["name"] = "lottmapgen:mordor_stone" }, { ["x"] = 5, ["meta"] = { ["fields"] = {  }, ["inventory"] = {  } }, ["param2"] = 0, ["y"] = 3, ["param1"] = 0, ["z"] = 17, ["name"] = "lottmapgen:mordor_stone" }, { ["x"] = 5, ["meta"] = { ["fields"] = {  }, ["inventory"] = {  } }, ["param2"] = 0, ["y"] = 4, ["param1"] = 0, ["z"] = 11, ["name"] = "lottmapgen:mordor_stone" }, { ["x"] = 5, ["meta"] = { ["fields"] = {  }, ["inventory"] = {  } }, ["param2"] = 0, ["y"] = 4, ["param1"] = 0, ["z"] = 12, ["name"] = "lottmapgen:mordor_stone" }, { ["x"] = 5, ["meta"] = { ["fields"] = {  }, ["inventory"] = {  } }, ["param2"] = 0, ["y"] = 4, ["param1"] = 0, ["z"] = 13, ["name"] = "lottmapgen:mordor_stone" }, { ["x"] = 5, ["meta"] = { ["fields"] = {  }, ["inventory"] = {  } }, ["param2"] = 0, ["y"] = 4, ["param1"] = 0, ["z"] = 14, ["name"] = "lottmapgen:mordor_stone" }, { ["x"] = 5, ["meta"] = { ["fields"] = {  }, ["inventory"] = {  } }, ["param2"] = 0, ["y"] = 4, ["param1"] = 0, ["z"] = 15, ["name"] = "lottmapgen:mordor_stone" }, { ["x"] = 5, ["meta"] = { ["fields"] = {  }, ["inventory"] = {  } }, ["param2"] = 0, ["y"] = 4, ["param1"] = 0, ["z"] = 16, ["name"] = "lottmapgen:mordor_stone" }, { ["x"] = 5, ["meta"] = { ["fields"] = {  }, ["inventory"] = {  } }, ["param2"] = 0, ["y"] = 4, ["param1"] = 0, ["z"] = 17, ["name"] = "lottmapgen:mordor_stone" }, { ["x"] = 5, ["meta"] = { ["fields"] = {  }, ["inventory"] = {  } }, ["param2"] = 0, ["y"] = 5, ["param1"] = 0, ["z"] = 11, ["name"] = "lottmapgen:mordor_stone" }, { ["x"] = 5, ["meta"] = { ["fields"] = {  }, ["inventory"] = {  } }, ["param2"] = 0, ["y"] = 5, ["param1"] = 0, ["z"] = 12, ["name"] = "lottmapgen:mordor_stone" }, { ["x"] = 5, ["meta"] = { ["fields"] = {  }, ["inventory"] = {  } }, ["param2"] = 0, ["y"] = 5, ["param1"] = 0, ["z"] = 13, ["name"] = "lottmapgen:mordor_stone" }, { ["x"] = 5, ["meta"] = { ["fields"] = {  }, ["inventory"] = {  } }, ["param2"] = 0, ["y"] = 5, ["param1"] = 0, ["z"] = 14, ["name"] = "lottmapgen:mordor_stone" }, { ["x"] = 5, ["meta"] = { ["fields"] = {  }, ["inventory"] = {  } }, ["param2"] = 0, ["y"] = 5, ["param1"] = 0, ["z"] = 15, ["name"] = "lottmapgen:mordor_stone" }, { ["x"] = 5, ["meta"] = { ["fields"] = {  }, ["inventory"] = {  } }, ["param2"] = 0, ["y"] = 5, ["param1"] = 0, ["z"] = 16, ["name"] = "lottmapgen:mordor_stone" }, { ["x"] = 5, ["meta"] = { ["fields"] = {  }, ["inventory"] = {  } }, ["param2"] = 0, ["y"] = 5, ["param1"] = 0, ["z"] = 17, ["name"] = "lottmapgen:mordor_stone" }, { ["x"] = 5, ["meta"] = { ["fields"] = {  }, ["inventory"] = {  } }, ["param2"] = 0, ["y"] = 6, ["param1"] = 0, ["z"] = 11, ["name"] = "lottmapgen:mordor_stone" }, { ["x"] = 5, ["meta"] = { ["fields"] = {  }, ["inventory"] = {  } }, ["param2"] = 0, ["y"] = 6, ["param1"] = 0, ["z"] = 12, ["name"] = "lottmapgen:mordor_stone" }, { ["x"] = 5, ["meta"] = { ["fields"] = {  }, ["inventory"] = {  } }, ["param2"] = 0, ["y"] = 6, ["param1"] = 0, ["z"] = 13, ["name"] = "lottmapgen:mordor_stone" }, { ["x"] = 5, ["meta"] = { ["fields"] = {  }, ["inventory"] = {  } }, ["param2"] = 0, ["y"] = 6, ["param1"] = 0, ["z"] = 14, ["name"] = "lottmapgen:mordor_stone" }, { ["x"] = 5, ["meta"] = { ["fields"] = {  }, ["inventory"] = {  } }, ["param2"] = 0, ["y"] = 6, ["param1"] = 0, ["z"] = 15, ["name"] = "lottmapgen:mordor_stone" }, { ["x"] = 5, ["meta"] = { ["fields"] = {  }, ["inventory"] = {  } }, ["param2"] = 0, ["y"] = 6, ["param1"] = 0, ["z"] = 16, ["name"] = "lottmapgen:mordor_stone" }, { ["x"] = 5, ["meta"] = { ["fields"] = {  }, ["inventory"] = {  } }, ["param2"] = 0, ["y"] = 6, ["param1"] = 0, ["z"] = 17, ["name"] = "lottmapgen:mordor_stone" }, { ["x"] = 5, ["meta"] = { ["fields"] = {  }, ["inventory"] = {  } }, ["param2"] = 0, ["y"] = 7, ["param1"] = 0, ["z"] = 11, ["name"] = "lottmapgen:mordor_stone" }, { ["x"] = 5, ["meta"] = { ["fields"] = {  }, ["inventory"] = {  } }, ["param2"] = 0, ["y"] = 7, ["param1"] = 0, ["z"] = 12, ["name"] = "lottmapgen:mordor_stone" }, { ["x"] = 5, ["meta"] = { ["fields"] = {  }, ["inventory"] = {  } }, ["param2"] = 0, ["y"] = 7, ["param1"] = 0, ["z"] = 13, ["name"] = "lottmapgen:mordor_stone" }, { ["x"] = 5, ["meta"] = { ["fields"] = {  }, ["inventory"] = {  } }, ["param2"] = 0, ["y"] = 7, ["param1"] = 0, ["z"] = 14, ["name"] = "lottmapgen:mordor_stone" }, { ["x"] = 5, ["meta"] = { ["fields"] = {  }, ["inventory"] = {  } }, ["param2"] = 0, ["y"] = 7, ["param1"] = 0, ["z"] = 15, ["name"] = "lottmapgen:mordor_stone" }, { ["x"] = 5, ["meta"] = { ["fields"] = {  }, ["inventory"] = {  } }, ["param2"] = 0, ["y"] = 7, ["param1"] = 0, ["z"] = 16, ["name"] = "lottmapgen:mordor_stone" }, { ["x"] = 5, ["meta"] = { ["fields"] = {  }, ["inventory"] = {  } }, ["param2"] = 0, ["y"] = 7, ["param1"] = 0, ["z"] = 17, ["name"] = "lottmapgen:mordor_stone" }, { ["x"] = 5, ["meta"] = { ["fields"] = {  }, ["inventory"] = {  } }, ["param2"] = 0, ["y"] = 8, ["param1"] = 0, ["z"] = 11, ["name"] = "lottmapgen:mordor_stone" }, { ["x"] = 5, ["meta"] = { ["fields"] = {  }, ["inventory"] = {  } }, ["param2"] = 0, ["y"] = 8, ["param1"] = 0, ["z"] = 12, ["name"] = "lottmapgen:mordor_stone" }, { ["x"] = 5, ["meta"] = { ["fields"] = {  }, ["inventory"] = {  } }, ["param2"] = 0, ["y"] = 8, ["param1"] = 0, ["z"] = 13, ["name"] = "lottmapgen:mordor_stone" }, { ["x"] = 5, ["meta"] = { ["fields"] = {  }, ["inventory"] = {  } }, ["param2"] = 0, ["y"] = 8, ["param1"] = 0, ["z"] = 14, ["name"] = "lottmapgen:mordor_stone" }, { ["x"] = 5, ["meta"] = { ["fields"] = {  }, ["inventory"] = {  } }, ["param2"] = 0, ["y"] = 8, ["param1"] = 0, ["z"] = 15, ["name"] = "lottmapgen:mordor_stone" }, { ["x"] = 5, ["meta"] = { ["fields"] = {  }, ["inventory"] = {  } }, ["param2"] = 0, ["y"] = 8, ["param1"] = 0, ["z"] = 16, ["name"] = "lottmapgen:mordor_stone" }, { ["x"] = 5, ["meta"] = { ["fields"] = {  }, ["inventory"] = {  } }, ["param2"] = 0, ["y"] = 8, ["param1"] = 0, ["z"] = 17, ["name"] = "lottmapgen:mordor_stone" }, { ["x"] = 5, ["meta"] = { ["fields"] = {  }, ["inventory"] = {  } }, ["param2"] = 0, ["y"] = 9, ["param1"] = 0, ["z"] = 11, ["name"] = "lottmapgen:mordor_stone" }, { ["x"] = 5, ["meta"] = { ["fields"] = {  }, ["inventory"] = {  } }, ["param2"] = 0, ["y"] = 9, ["param1"] = 0, ["z"] = 12, ["name"] = "lottmapgen:mordor_stone" }, { ["x"] = 5, ["meta"] = { ["fields"] = {  }, ["inventory"] = {  } }, ["param2"] = 0, ["y"] = 9, ["param1"] = 0, ["z"] = 13, ["name"] = "lottmapgen:mordor_stone" }, { ["x"] = 5, ["meta"] = { ["fields"] = {  }, ["inventory"] = {  } }, ["param2"] = 0, ["y"] = 9, ["param1"] = 0, ["z"] = 14, ["name"] = "lottmapgen:mordor_stone" }, { ["x"] = 5, ["meta"] = { ["fields"] = {  }, ["inventory"] = {  } }, ["param2"] = 0, ["y"] = 9, ["param1"] = 0, ["z"] = 15, ["name"] = "lottmapgen:mordor_stone" }, { ["x"] = 5, ["meta"] = { ["fields"] = {  }, ["inventory"] = {  } }, ["param2"] = 0, ["y"] = 9, ["param1"] = 0, ["z"] = 16, ["name"] = "lottmapgen:mordor_stone" }, { ["x"] = 5, ["meta"] = { ["fields"] = {  }, ["inventory"] = {  } }, ["param2"] = 0, ["y"] = 9, ["param1"] = 0, ["z"] = 17, ["name"] = "lottmapgen:mordor_stone" }, { ["x"] = 5, ["meta"] = { ["fields"] = {  }, ["inventory"] = {  } }, ["param2"] = 0, ["y"] = 10, ["param1"] = 0, ["z"] = 11, ["name"] = "lottmapgen:mordor_stone" }, { ["x"] = 5, ["meta"] = { ["fields"] = {  }, ["inventory"] = {  } }, ["param2"] = 0, ["y"] = 10, ["param1"] = 0, ["z"] = 12, ["name"] = "lottmapgen:mordor_stone" }, { ["x"] = 5, ["meta"] = { ["fields"] = {  }, ["inventory"] = {  } }, ["param2"] = 0, ["y"] = 10, ["param1"] = 0, ["z"] = 13, ["name"] = "lottmapgen:mordor_stone" }, { ["x"] = 5, ["meta"] = { ["fields"] = {  }, ["inventory"] = {  } }, ["param2"] = 0, ["y"] = 10, ["param1"] = 0, ["z"] = 14, ["name"] = "lottmapgen:mordor_stone" }, { ["x"] = 5, ["meta"] = { ["fields"] = {  }, ["inventory"] = {  } }, ["param2"] = 0, ["y"] = 10, ["param1"] = 0, ["z"] = 15, ["name"] = "lottmapgen:mordor_stone" }, { ["x"] = 5, ["meta"] = { ["fields"] = {  }, ["inventory"] = {  } }, ["param2"] = 0, ["y"] = 10, ["param1"] = 0, ["z"] = 16, ["name"] = "lottmapgen:mordor_stone" }, { ["x"] = 5, ["meta"] = { ["fields"] = {  }, ["inventory"] = {  } }, ["param2"] = 0, ["y"] = 10, ["param1"] = 0, ["z"] = 17, ["name"] = "lottmapgen:mordor_stone" }, { ["x"] = 5, ["meta"] = { ["fields"] = {  }, ["inventory"] = {  } }, ["param2"] = 0, ["y"] = 11, ["param1"] = 0, ["z"] = 11, ["name"] = "lottmapgen:mordor_stone" }, { ["x"] = 5, ["meta"] = { ["fields"] = {  }, ["inventory"] = {  } }, ["param2"] = 0, ["y"] = 11, ["param1"] = 0, ["z"] = 12, ["name"] = "lottmapgen:mordor_stone" }, { ["x"] = 5, ["meta"] = { ["fields"] = {  }, ["inventory"] = {  } }, ["param2"] = 0, ["y"] = 11, ["param1"] = 0, ["z"] = 13, ["name"] = "lottmapgen:mordor_stone" }, { ["x"] = 5, ["meta"] = { ["fields"] = {  }, ["inventory"] = {  } }, ["param2"] = 0, ["y"] = 11, ["param1"] = 0, ["z"] = 14, ["name"] = "lottmapgen:mordor_stone" }, { ["x"] = 5, ["meta"] = { ["fields"] = {  }, ["inventory"] = {  } }, ["param2"] = 0, ["y"] = 11, ["param1"] = 0, ["z"] = 15, ["name"] = "lottmapgen:mordor_stone" }, { ["x"] = 5, ["meta"] = { ["fields"] = {  }, ["inventory"] = {  } }, ["param2"] = 0, ["y"] = 11, ["param1"] = 0, ["z"] = 16, ["name"] = "lottmapgen:mordor_stone" }, { ["x"] = 5, ["meta"] = { ["fields"] = {  }, ["inventory"] = {  } }, ["param2"] = 0, ["y"] = 11, ["param1"] = 0, ["z"] = 17, ["name"] = "lottmapgen:mordor_stone" }, { ["x"] = 5, ["meta"] = { ["fields"] = {  }, ["inventory"] = {  } }, ["param2"] = 0, ["y"] = 12, ["param1"] = 0, ["z"] = 9, ["name"] = "lottmapgen:mordor_stone" }, { ["x"] = 5, ["meta"] = { ["fields"] = {  }, ["inventory"] = {  } }, ["param2"] = 0, ["y"] = 12, ["param1"] = 0, ["z"] = 10, ["name"] = "lottmapgen:mordor_stone" }, { ["x"] = 5, ["meta"] = { ["fields"] = {  }, ["inventory"] = {  } }, ["param2"] = 0, ["y"] = 12, ["param1"] = 0, ["z"] = 11, ["name"] = "lottmapgen:mordor_stone" }, { ["x"] = 5, ["meta"] = { ["fields"] = {  }, ["inventory"] = {  } }, ["param2"] = 0, ["y"] = 12, ["param1"] = 0, ["z"] = 12, ["name"] = "lottmapgen:mordor_stone" }, { ["x"] = 5, ["meta"] = { ["fields"] = {  }, ["inventory"] = {  } }, ["param2"] = 0, ["y"] = 12, ["param1"] = 0, ["z"] = 13, ["name"] = "lottmapgen:mordor_stone" }, { ["x"] = 5, ["meta"] = { ["fields"] = {  }, ["inventory"] = {  } }, ["param2"] = 0, ["y"] = 12, ["param1"] = 0, ["z"] = 14, ["name"] = "lottmapgen:mordor_stone" }, { ["x"] = 5, ["meta"] = { ["fields"] = {  }, ["inventory"] = {  } }, ["param2"] = 0, ["y"] = 12, ["param1"] = 0, ["z"] = 15, ["name"] = "lottmapgen:mordor_stone" }, { ["x"] = 5, ["meta"] = { ["fields"] = {  }, ["inventory"] = {  } }, ["param2"] = 0, ["y"] = 12, ["param1"] = 0, ["z"] = 16, ["name"] = "lottmapgen:mordor_stone" }, { ["x"] = 5, ["meta"] = { ["fields"] = {  }, ["inventory"] = {  } }, ["param2"] = 0, ["y"] = 12, ["param1"] = 0, ["z"] = 17, ["name"] = "lottmapgen:mordor_stone" }, { ["x"] = 5, ["meta"] = { ["fields"] = {  }, ["inventory"] = {  } }, ["param2"] = 0, ["y"] = 12, ["param1"] = 0, ["z"] = 18, ["name"] = "lottmapgen:mordor_stone" }, { ["x"] = 5, ["meta"] = { ["fields"] = {  }, ["inventory"] = {  } }, ["param2"] = 0, ["y"] = 13, ["param1"] = 0, ["z"] = 9, ["name"] = "lottmapgen:mordor_stone" }, { ["x"] = 5, ["meta"] = { ["fields"] = {  }, ["inventory"] = {  } }, ["param2"] = 0, ["y"] = 13, ["param1"] = 0, ["z"] = 10, ["name"] = "lottmapgen:mordor_stone" }, { ["x"] = 5, ["meta"] = { ["fields"] = {  }, ["inventory"] = {  } }, ["param2"] = 0, ["y"] = 13, ["param1"] = 15, ["z"] = 11, ["name"] = "lottother:air" }, { ["x"] = 5, ["meta"] = { ["fields"] = {  }, ["inventory"] = {  } }, ["param2"] = 0, ["y"] = 13, ["param1"] = 15, ["z"] = 12, ["name"] = "lottother:air" }, { ["x"] = 5, ["meta"] = { ["fields"] = {  }, ["inventory"] = {  } }, ["param2"] = 0, ["y"] = 13, ["param1"] = 31, ["z"] = 13, ["name"] = "lottother:air" }, { ["x"] = 5, ["meta"] = { ["fields"] = {  }, ["inventory"] = {  } }, ["param2"] = 0, ["y"] = 13, ["param1"] = 47, ["z"] = 14, ["name"] = "lottother:air" }, { ["x"] = 5, ["meta"] = { ["fields"] = {  }, ["inventory"] = {  } }, ["param2"] = 0, ["y"] = 13, ["param1"] = 31, ["z"] = 15, ["name"] = "lottother:air" }, { ["x"] = 5, ["meta"] = { ["fields"] = {  }, ["inventory"] = {  } }, ["param2"] = 0, ["y"] = 13, ["param1"] = 15, ["z"] = 16, ["name"] = "lottother:air" }, { ["x"] = 5, ["meta"] = { ["fields"] = {  }, ["inventory"] = {  } }, ["param2"] = 0, ["y"] = 13, ["param1"] = 15, ["z"] = 17, ["name"] = "lottother:air" }, { ["x"] = 5, ["meta"] = { ["fields"] = {  }, ["inventory"] = {  } }, ["param2"] = 0, ["y"] = 13, ["param1"] = 0, ["z"] = 18, ["name"] = "lottmapgen:mordor_stone" }, { ["x"] = 5, ["meta"] = { ["fields"] = {  }, ["inventory"] = {  } }, ["param2"] = 0, ["y"] = 13, ["param1"] = 0, ["z"] = 19, ["name"] = "lottmapgen:mordor_stone" }, { ["x"] = 5, ["meta"] = { ["fields"] = {  }, ["inventory"] = {  } }, ["param2"] = 0, ["y"] = 14, ["param1"] = 0, ["z"] = 9, ["name"] = "lottmapgen:mordor_stone" }, { ["x"] = 5, ["meta"] = { ["fields"] = {  }, ["inventory"] = {  } }, ["param2"] = 0, ["y"] = 14, ["param1"] = 0, ["z"] = 10, ["name"] = "lottmapgen:mordor_stone" }, { ["x"] = 5, ["meta"] = { ["fields"] = {  }, ["inventory"] = {  } }, ["param2"] = 0, ["y"] = 14, ["param1"] = 15, ["z"] = 11, ["name"] = "lottother:air" }, { ["x"] = 5, ["meta"] = { ["fields"] = {  }, ["inventory"] = {  } }, ["param2"] = 0, ["y"] = 14, ["param1"] = 31, ["z"] = 12, ["name"] = "lottother:air" }, { ["x"] = 5, ["meta"] = { ["fields"] = {  }, ["inventory"] = {  } }, ["param2"] = 0, ["y"] = 14, ["param1"] = 47, ["z"] = 13, ["name"] = "lottother:air" }, { ["x"] = 5, ["meta"] = { ["fields"] = {  }, ["inventory"] = {  } }, ["param2"] = 0, ["y"] = 14, ["param1"] = 63, ["z"] = 14, ["name"] = "lottother:air" }, { ["x"] = 5, ["meta"] = { ["fields"] = {  }, ["inventory"] = {  } }, ["param2"] = 0, ["y"] = 14, ["param1"] = 47, ["z"] = 15, ["name"] = "lottother:air" }, { ["x"] = 5, ["meta"] = { ["fields"] = {  }, ["inventory"] = {  } }, ["param2"] = 0, ["y"] = 14, ["param1"] = 31, ["z"] = 16, ["name"] = "lottother:air" }, { ["x"] = 5, ["meta"] = { ["fields"] = {  }, ["inventory"] = {  } }, ["param2"] = 0, ["y"] = 14, ["param1"] = 15, ["z"] = 17, ["name"] = "lottother:air" }, { ["x"] = 5, ["meta"] = { ["fields"] = {  }, ["inventory"] = {  } }, ["param2"] = 0, ["y"] = 14, ["param1"] = 0, ["z"] = 18, ["name"] = "lottmapgen:mordor_stone" }, { ["x"] = 5, ["meta"] = { ["fields"] = {  }, ["inventory"] = {  } }, ["param2"] = 0, ["y"] = 14, ["param1"] = 0, ["z"] = 19, ["name"] = "lottmapgen:mordor_stone" }, { ["x"] = 5, ["meta"] = { ["fields"] = {  }, ["inventory"] = {  } }, ["param2"] = 0, ["y"] = 15, ["param1"] = 0, ["z"] = 9, ["name"] = "lottmapgen:mordor_stone" }, { ["x"] = 5, ["meta"] = { ["fields"] = {  }, ["inventory"] = {  } }, ["param2"] = 0, ["y"] = 15, ["param1"] = 0, ["z"] = 10, ["name"] = "lottmapgen:mordor_stone" }, { ["x"] = 5, ["meta"] = { ["fields"] = {  }, ["inventory"] = {  } }, ["param2"] = 0, ["y"] = 15, ["param1"] = 31, ["z"] = 11, ["name"] = "lottother:air" }, { ["x"] = 5, ["meta"] = { ["fields"] = {  }, ["inventory"] = {  } }, ["param2"] = 0, ["y"] = 15, ["param1"] = 47, ["z"] = 12, ["name"] = "lottother:air" }, { ["x"] = 5, ["meta"] = { ["fields"] = {  }, ["inventory"] = {  } }, ["param2"] = 0, ["y"] = 15, ["param1"] = 63, ["z"] = 13, ["name"] = "lottother:air" }, { ["x"] = 5, ["meta"] = { ["fields"] = {  }, ["inventory"] = {  } }, ["param2"] = 0, ["y"] = 15, ["param1"] = 79, ["z"] = 14, ["name"] = "lottother:air" }, { ["x"] = 5, ["meta"] = { ["fields"] = {  }, ["inventory"] = {  } }, ["param2"] = 0, ["y"] = 15, ["param1"] = 63, ["z"] = 15, ["name"] = "lottother:air" }, { ["x"] = 5, ["meta"] = { ["fields"] = {  }, ["inventory"] = {  } }, ["param2"] = 0, ["y"] = 15, ["param1"] = 47, ["z"] = 16, ["name"] = "lottother:air" }, { ["x"] = 5, ["meta"] = { ["fields"] = {  }, ["inventory"] = {  } }, ["param2"] = 0, ["y"] = 15, ["param1"] = 31, ["z"] = 17, ["name"] = "lottother:air" }, { ["x"] = 5, ["meta"] = { ["fields"] = {  }, ["inventory"] = {  } }, ["param2"] = 0, ["y"] = 15, ["param1"] = 0, ["z"] = 18, ["name"] = "lottmapgen:mordor_stone" }, { ["x"] = 5, ["meta"] = { ["fields"] = {  }, ["inventory"] = {  } }, ["param2"] = 0, ["y"] = 15, ["param1"] = 0, ["z"] = 19, ["name"] = "lottmapgen:mordor_stone" }, { ["x"] = 6, ["meta"] = { ["fields"] = {  }, ["inventory"] = {  } }, ["param2"] = 0, ["y"] = 0, ["param1"] = 0, ["z"] = 5, ["name"] = "lottother:mordor_stone" }, { ["x"] = 6, ["meta"] = { ["fields"] = {  }, ["inventory"] = {  } }, ["param2"] = 0, ["y"] = 0, ["param1"] = 0, ["z"] = 6, ["name"] = "lottother:mordor_stone" }, { ["x"] = 6, ["meta"] = { ["fields"] = {  }, ["inventory"] = {  } }, ["param2"] = 0, ["y"] = 0, ["param1"] = 15, ["z"] = 7, ["name"] = "lottother:mordor_stone" }, { ["x"] = 6, ["meta"] = { ["fields"] = {  }, ["inventory"] = {  } }, ["param2"] = 0, ["y"] = 0, ["param1"] = 13, ["z"] = 8, ["name"] = "lottother:mordor_stone" }, { ["x"] = 6, ["meta"] = { ["fields"] = {  }, ["inventory"] = {  } }, ["param2"] = 0, ["y"] = 0, ["param1"] = 12, ["z"] = 9, ["name"] = "lottother:mordor_stone" }, { ["x"] = 6, ["meta"] = { ["fields"] = {  }, ["inventory"] = {  } }, ["param2"] = 0, ["y"] = 0, ["param1"] = 11, ["z"] = 10, ["name"] = "lottother:mordor_stone" }, { ["x"] = 6, ["meta"] = { ["fields"] = {  }, ["inventory"] = {  } }, ["param2"] = 0, ["y"] = 0, ["param1"] = 11, ["z"] = 11, ["name"] = "lottother:mordor_stone" }, { ["x"] = 6, ["meta"] = { ["fields"] = {  }, ["inventory"] = {  } }, ["param2"] = 0, ["y"] = 0, ["param1"] = 11, ["z"] = 12, ["name"] = "lottother:mordor_stone" }, { ["x"] = 6, ["meta"] = { ["fields"] = {  }, ["inventory"] = {  } }, ["param2"] = 0, ["y"] = 0, ["param1"] = 10, ["z"] = 13, ["name"] = "lottother:mordor_stone" }, { ["x"] = 6, ["meta"] = { ["fields"] = {  }, ["inventory"] = {  } }, ["param2"] = 0, ["y"] = 0, ["param1"] = 9, ["z"] = 14, ["name"] = "lottother:mordor_stone" }, { ["x"] = 6, ["meta"] = { ["fields"] = {  }, ["inventory"] = {  } }, ["param2"] = 0, ["y"] = 0, ["param1"] = 10, ["z"] = 15, ["name"] = "lottother:mordor_stone" }, { ["x"] = 6, ["meta"] = { ["fields"] = {  }, ["inventory"] = {  } }, ["param2"] = 0, ["y"] = 0, ["param1"] = 11, ["z"] = 16, ["name"] = "lottother:mordor_stone" }, { ["x"] = 6, ["meta"] = { ["fields"] = {  }, ["inventory"] = {  } }, ["param2"] = 0, ["y"] = 0, ["param1"] = 11, ["z"] = 17, ["name"] = "lottother:mordor_stone" }, { ["x"] = 6, ["meta"] = { ["fields"] = {  }, ["inventory"] = {  } }, ["param2"] = 0, ["y"] = 0, ["param1"] = 11, ["z"] = 18, ["name"] = "lottother:mordor_stone" }, { ["x"] = 6, ["meta"] = { ["fields"] = {  }, ["inventory"] = {  } }, ["param2"] = 0, ["y"] = 0, ["param1"] = 12, ["z"] = 19, ["name"] = "lottother:mordor_stone" }, { ["x"] = 6, ["meta"] = { ["fields"] = {  }, ["inventory"] = {  } }, ["param2"] = 0, ["y"] = 0, ["param1"] = 13, ["z"] = 20, ["name"] = "lottother:mordor_stone" }, { ["x"] = 6, ["meta"] = { ["fields"] = {  }, ["inventory"] = {  } }, ["param2"] = 0, ["y"] = 0, ["param1"] = 15, ["z"] = 21, ["name"] = "lottother:mordor_stone" }, { ["x"] = 6, ["meta"] = { ["fields"] = {  }, ["inventory"] = {  } }, ["param2"] = 0, ["y"] = 0, ["param1"] = 0, ["z"] = 22, ["name"] = "lottother:mordor_stone" }, { ["x"] = 6, ["meta"] = { ["fields"] = {  }, ["inventory"] = {  } }, ["param2"] = 0, ["y"] = 0, ["param1"] = 0, ["z"] = 23, ["name"] = "lottother:mordor_stone" }, { ["x"] = 6, ["meta"] = { ["fields"] = {  }, ["inventory"] = {  } }, ["param2"] = 0, ["y"] = 1, ["param1"] = 15, ["z"] = 7, ["name"] = "lottother:mordor_stone" }, { ["x"] = 6, ["meta"] = { ["fields"] = {  }, ["inventory"] = {  } }, ["param2"] = 0, ["y"] = 1, ["param1"] = 13, ["z"] = 8, ["name"] = "lottother:mordor_stone" }, { ["x"] = 6, ["meta"] = { ["fields"] = {  }, ["inventory"] = {  } }, ["param2"] = 0, ["y"] = 1, ["param1"] = 12, ["z"] = 9, ["name"] = "lottother:mordor_stone" }, { ["x"] = 6, ["meta"] = { ["fields"] = {  }, ["inventory"] = {  } }, ["param2"] = 0, ["y"] = 1, ["param1"] = 11, ["z"] = 10, ["name"] = "lottother:mordor_stone" }, { ["x"] = 6, ["meta"] = { ["fields"] = {  }, ["inventory"] = {  } }, ["param2"] = 0, ["y"] = 1, ["param1"] = 11, ["z"] = 11, ["name"] = "lottother:mordor_stone" }, { ["x"] = 6, ["meta"] = { ["fields"] = {  }, ["inventory"] = {  } }, ["param2"] = 0, ["y"] = 1, ["param1"] = 11, ["z"] = 12, ["name"] = "lottother:mordor_stone" }, { ["x"] = 6, ["meta"] = { ["fields"] = {  }, ["inventory"] = {  } }, ["param2"] = 0, ["y"] = 1, ["param1"] = 10, ["z"] = 13, ["name"] = "lottother:mordor_stone" }, { ["x"] = 6, ["meta"] = { ["fields"] = {  }, ["inventory"] = {  } }, ["param2"] = 0, ["y"] = 1, ["param1"] = 9, ["z"] = 14, ["name"] = "lottother:mordor_stone" }, { ["x"] = 6, ["meta"] = { ["fields"] = {  }, ["inventory"] = {  } }, ["param2"] = 0, ["y"] = 1, ["param1"] = 10, ["z"] = 15, ["name"] = "lottother:mordor_stone" }, { ["x"] = 6, ["meta"] = { ["fields"] = {  }, ["inventory"] = {  } }, ["param2"] = 0, ["y"] = 1, ["param1"] = 11, ["z"] = 16, ["name"] = "lottother:mordor_stone" }, { ["x"] = 6, ["meta"] = { ["fields"] = {  }, ["inventory"] = {  } }, ["param2"] = 0, ["y"] = 1, ["param1"] = 11, ["z"] = 17, ["name"] = "lottother:mordor_stone" }, { ["x"] = 6, ["meta"] = { ["fields"] = {  }, ["inventory"] = {  } }, ["param2"] = 0, ["y"] = 1, ["param1"] = 11, ["z"] = 18, ["name"] = "lottother:mordor_stone" }, { ["x"] = 6, ["meta"] = { ["fields"] = {  }, ["inventory"] = {  } }, ["param2"] = 0, ["y"] = 1, ["param1"] = 12, ["z"] = 19, ["name"] = "lottother:mordor_stone" }, { ["x"] = 6, ["meta"] = { ["fields"] = {  }, ["inventory"] = {  } }, ["param2"] = 0, ["y"] = 1, ["param1"] = 13, ["z"] = 20, ["name"] = "lottother:mordor_stone" }, { ["x"] = 6, ["meta"] = { ["fields"] = {  }, ["inventory"] = {  } }, ["param2"] = 0, ["y"] = 1, ["param1"] = 15, ["z"] = 21, ["name"] = "lottother:mordor_stone" }, { ["x"] = 6, ["meta"] = { ["fields"] = {  }, ["inventory"] = {  } }, ["param2"] = 0, ["y"] = 2, ["param1"] = 0, ["z"] = 9, ["name"] = "lottmapgen:mordor_stone" }, { ["x"] = 6, ["meta"] = { ["fields"] = {  }, ["inventory"] = {  } }, ["param2"] = 0, ["y"] = 2, ["param1"] = 0, ["z"] = 10, ["name"] = "lottmapgen:mordor_stone" }, { ["x"] = 6, ["meta"] = { ["fields"] = {  }, ["inventory"] = {  } }, ["param2"] = 0, ["y"] = 2, ["param1"] = 0, ["z"] = 11, ["name"] = "lottmapgen:mordor_stone" }, { ["x"] = 6, ["meta"] = { ["fields"] = {  }, ["inventory"] = {  } }, ["param2"] = 0, ["y"] = 2, ["param1"] = 0, ["z"] = 12, ["name"] = "lottmapgen:mordor_stone" }, { ["x"] = 6, ["meta"] = { ["fields"] = {  }, ["inventory"] = {  } }, ["param2"] = 0, ["y"] = 2, ["param1"] = 0, ["z"] = 13, ["name"] = "lottmapgen:mordor_stone" }, { ["x"] = 6, ["meta"] = { ["fields"] = {  }, ["inventory"] = {  } }, ["param2"] = 0, ["y"] = 2, ["param1"] = 0, ["z"] = 14, ["name"] = "lottblocks:orc_brick" }, { ["x"] = 6, ["meta"] = { ["fields"] = {  }, ["inventory"] = {  } }, ["param2"] = 0, ["y"] = 2, ["param1"] = 0, ["z"] = 15, ["name"] = "lottmapgen:mordor_stone" }, { ["x"] = 6, ["meta"] = { ["fields"] = {  }, ["inventory"] = {  } }, ["param2"] = 0, ["y"] = 2, ["param1"] = 0, ["z"] = 16, ["name"] = "lottmapgen:mordor_stone" }, { ["x"] = 6, ["meta"] = { ["fields"] = {  }, ["inventory"] = {  } }, ["param2"] = 0, ["y"] = 2, ["param1"] = 0, ["z"] = 17, ["name"] = "lottmapgen:mordor_stone" }, { ["x"] = 6, ["meta"] = { ["fields"] = {  }, ["inventory"] = {  } }, ["param2"] = 0, ["y"] = 2, ["param1"] = 0, ["z"] = 18, ["name"] = "lottmapgen:mordor_stone" }, { ["x"] = 6, ["meta"] = { ["fields"] = {  }, ["inventory"] = {  } }, ["param2"] = 0, ["y"] = 2, ["param1"] = 0, ["z"] = 19, ["name"] = "lottmapgen:mordor_stone" }, { ["x"] = 6, ["meta"] = { ["fields"] = {  }, ["inventory"] = {  } }, ["param2"] = 0, ["y"] = 3, ["param1"] = 0, ["z"] = 9, ["name"] = "lottmapgen:mordor_stone" }, { ["x"] = 6, ["meta"] = { ["fields"] = {  }, ["inventory"] = {  } }, ["param2"] = 0, ["y"] = 3, ["param1"] = 0, ["z"] = 10, ["name"] = "lottmapgen:mordor_stone" }, { ["x"] = 6, ["meta"] = { ["fields"] = {  }, ["inventory"] = {  } }, ["param2"] = 0, ["y"] = 3, ["param1"] = 0, ["z"] = 11, ["name"] = "lottmapgen:mordor_stone" }, { ["x"] = 6, ["meta"] = { ["fields"] = {  }, ["inventory"] = {  } }, ["param2"] = 0, ["y"] = 3, ["param1"] = 170, ["z"] = 12, ["name"] = "lottother:air" }, { ["x"] = 6, ["meta"] = { ["fields"] = {  }, ["inventory"] = {  } }, ["param2"] = 3, ["y"] = 3, ["param1"] = 0, ["z"] = 13, ["name"] = "lottother:orc_torch" }, { ["x"] = 6, ["meta"] = { ["fields"] = {  }, ["inventory"] = {  } }, ["param2"] = 0, ["y"] = 3, ["param1"] = 170, ["z"] = 14, ["name"] = "lottother:mordorms_off" }, { ["x"] = 6, ["meta"] = { ["fields"] = {  }, ["inventory"] = {  } }, ["param2"] = 3, ["y"] = 3, ["param1"] = 0, ["z"] = 15, ["name"] = "lottother:orc_torch" }, { ["x"] = 6, ["meta"] = { ["fields"] = {  }, ["inventory"] = {  } }, ["param2"] = 0, ["y"] = 3, ["param1"] = 170, ["z"] = 16, ["name"] = "lottother:air" }, { ["x"] = 6, ["meta"] = { ["fields"] = {  }, ["inventory"] = {  } }, ["param2"] = 0, ["y"] = 3, ["param1"] = 0, ["z"] = 17, ["name"] = "lottmapgen:mordor_stone" }, { ["x"] = 6, ["meta"] = { ["fields"] = {  }, ["inventory"] = {  } }, ["param2"] = 0, ["y"] = 3, ["param1"] = 0, ["z"] = 18, ["name"] = "lottmapgen:mordor_stone" }, { ["x"] = 6, ["meta"] = { ["fields"] = {  }, ["inventory"] = {  } }, ["param2"] = 0, ["y"] = 3, ["param1"] = 0, ["z"] = 19, ["name"] = "lottmapgen:mordor_stone" }, { ["x"] = 6, ["meta"] = { ["fields"] = {  }, ["inventory"] = {  } }, ["param2"] = 0, ["y"] = 4, ["param1"] = 0, ["z"] = 9, ["name"] = "lottmapgen:mordor_stone" }, { ["x"] = 6, ["meta"] = { ["fields"] = {  }, ["inventory"] = {  } }, ["param2"] = 0, ["y"] = 4, ["param1"] = 0, ["z"] = 10, ["name"] = "lottmapgen:mordor_stone" }, { ["x"] = 6, ["meta"] = { ["fields"] = {  }, ["inventory"] = {  } }, ["param2"] = 0, ["y"] = 4, ["param1"] = 0, ["z"] = 11, ["name"] = "lottmapgen:mordor_stone" }, { ["x"] = 6, ["meta"] = { ["fields"] = {  }, ["inventory"] = {  } }, ["param2"] = 0, ["y"] = 4, ["param1"] = 170, ["z"] = 12, ["name"] = "lottother:air" }, { ["x"] = 6, ["meta"] = { ["fields"] = {  }, ["inventory"] = {  } }, ["param2"] = 3, ["y"] = 4, ["param1"] = 0, ["z"] = 13, ["name"] = "lottother:orc_torch" }, { ["x"] = 6, ["meta"] = { ["fields"] = {  }, ["inventory"] = {  } }, ["param2"] = 0, ["y"] = 4, ["param1"] = 170, ["z"] = 14, ["name"] = "lottother:air" }, { ["x"] = 6, ["meta"] = { ["fields"] = {  }, ["inventory"] = {  } }, ["param2"] = 3, ["y"] = 4, ["param1"] = 0, ["z"] = 15, ["name"] = "lottother:orc_torch" }, { ["x"] = 6, ["meta"] = { ["fields"] = {  }, ["inventory"] = {  } }, ["param2"] = 0, ["y"] = 4, ["param1"] = 170, ["z"] = 16, ["name"] = "lottother:air" }, { ["x"] = 6, ["meta"] = { ["fields"] = {  }, ["inventory"] = {  } }, ["param2"] = 0, ["y"] = 4, ["param1"] = 0, ["z"] = 17, ["name"] = "lottmapgen:mordor_stone" }, { ["x"] = 6, ["meta"] = { ["fields"] = {  }, ["inventory"] = {  } }, ["param2"] = 0, ["y"] = 4, ["param1"] = 0, ["z"] = 18, ["name"] = "lottmapgen:mordor_stone" }, { ["x"] = 6, ["meta"] = { ["fields"] = {  }, ["inventory"] = {  } }, ["param2"] = 0, ["y"] = 4, ["param1"] = 0, ["z"] = 19, ["name"] = "lottmapgen:mordor_stone" }, { ["x"] = 6, ["meta"] = { ["fields"] = {  }, ["inventory"] = {  } }, ["param2"] = 0, ["y"] = 5, ["param1"] = 0, ["z"] = 9, ["name"] = "lottmapgen:mordor_stone" }, { ["x"] = 6, ["meta"] = { ["fields"] = {  }, ["inventory"] = {  } }, ["param2"] = 0, ["y"] = 5, ["param1"] = 0, ["z"] = 10, ["name"] = "lottmapgen:mordor_stone" }, { ["x"] = 6, ["meta"] = { ["fields"] = {  }, ["inventory"] = {  } }, ["param2"] = 0, ["y"] = 5, ["param1"] = 0, ["z"] = 11, ["name"] = "lottmapgen:mordor_stone" }, { ["x"] = 6, ["meta"] = { ["fields"] = {  }, ["inventory"] = {  } }, ["param2"] = 0, ["y"] = 5, ["param1"] = 170, ["z"] = 12, ["name"] = "lottother:air" }, { ["x"] = 6, ["meta"] = { ["fields"] = {  }, ["inventory"] = {  } }, ["param2"] = 3, ["y"] = 5, ["param1"] = 0, ["z"] = 13, ["name"] = "lottother:orc_torch" }, { ["x"] = 6, ["meta"] = { ["fields"] = {  }, ["inventory"] = {  } }, ["param2"] = 0, ["y"] = 5, ["param1"] = 170, ["z"] = 14, ["name"] = "lottother:air" }, { ["x"] = 6, ["meta"] = { ["fields"] = {  }, ["inventory"] = {  } }, ["param2"] = 3, ["y"] = 5, ["param1"] = 0, ["z"] = 15, ["name"] = "lottother:orc_torch" }, { ["x"] = 6, ["meta"] = { ["fields"] = {  }, ["inventory"] = {  } }, ["param2"] = 0, ["y"] = 5, ["param1"] = 170, ["z"] = 16, ["name"] = "lottother:air" }, { ["x"] = 6, ["meta"] = { ["fields"] = {  }, ["inventory"] = {  } }, ["param2"] = 0, ["y"] = 5, ["param1"] = 0, ["z"] = 17, ["name"] = "lottmapgen:mordor_stone" }, { ["x"] = 6, ["meta"] = { ["fields"] = {  }, ["inventory"] = {  } }, ["param2"] = 0, ["y"] = 5, ["param1"] = 0, ["z"] = 18, ["name"] = "lottmapgen:mordor_stone" }, { ["x"] = 6, ["meta"] = { ["fields"] = {  }, ["inventory"] = {  } }, ["param2"] = 0, ["y"] = 5, ["param1"] = 0, ["z"] = 19, ["name"] = "lottmapgen:mordor_stone" }, { ["x"] = 6, ["meta"] = { ["fields"] = {  }, ["inventory"] = {  } }, ["param2"] = 0, ["y"] = 6, ["param1"] = 0, ["z"] = 9, ["name"] = "lottmapgen:mordor_stone" }, { ["x"] = 6, ["meta"] = { ["fields"] = {  }, ["inventory"] = {  } }, ["param2"] = 0, ["y"] = 6, ["param1"] = 0, ["z"] = 10, ["name"] = "lottmapgen:mordor_stone" }, { ["x"] = 6, ["meta"] = { ["fields"] = {  }, ["inventory"] = {  } }, ["param2"] = 0, ["y"] = 6, ["param1"] = 0, ["z"] = 11, ["name"] = "lottmapgen:mordor_stone" }, { ["x"] = 6, ["meta"] = { ["fields"] = {  }, ["inventory"] = {  } }, ["param2"] = 0, ["y"] = 6, ["param1"] = 153, ["z"] = 12, ["name"] = "lottother:air" }, { ["x"] = 6, ["meta"] = { ["fields"] = {  }, ["inventory"] = {  } }, ["param2"] = 0, ["y"] = 6, ["param1"] = 170, ["z"] = 13, ["name"] = "lottother:air" }, { ["x"] = 6, ["meta"] = { ["fields"] = {  }, ["inventory"] = {  } }, ["param2"] = 3, ["y"] = 6, ["param1"] = 0, ["z"] = 14, ["name"] = "lottother:orc_torch" }, { ["x"] = 6, ["meta"] = { ["fields"] = {  }, ["inventory"] = {  } }, ["param2"] = 0, ["y"] = 6, ["param1"] = 170, ["z"] = 15, ["name"] = "lottother:air" }, { ["x"] = 6, ["meta"] = { ["fields"] = {  }, ["inventory"] = {  } }, ["param2"] = 0, ["y"] = 6, ["param1"] = 153, ["z"] = 16, ["name"] = "lottother:air" }, { ["x"] = 6, ["meta"] = { ["fields"] = {  }, ["inventory"] = {  } }, ["param2"] = 0, ["y"] = 6, ["param1"] = 0, ["z"] = 17, ["name"] = "lottmapgen:mordor_stone" }, { ["x"] = 6, ["meta"] = { ["fields"] = {  }, ["inventory"] = {  } }, ["param2"] = 0, ["y"] = 6, ["param1"] = 0, ["z"] = 18, ["name"] = "lottmapgen:mordor_stone" }, { ["x"] = 6, ["meta"] = { ["fields"] = {  }, ["inventory"] = {  } }, ["param2"] = 0, ["y"] = 6, ["param1"] = 0, ["z"] = 19, ["name"] = "lottmapgen:mordor_stone" }, { ["x"] = 6, ["meta"] = { ["fields"] = {  }, ["inventory"] = {  } }, ["param2"] = 0, ["y"] = 7, ["param1"] = 0, ["z"] = 9, ["name"] = "lottmapgen:mordor_stone" }, { ["x"] = 6, ["meta"] = { ["fields"] = {  }, ["inventory"] = {  } }, ["param2"] = 0, ["y"] = 7, ["param1"] = 0, ["z"] = 10, ["name"] = "lottmapgen:mordor_stone" }, { ["x"] = 6, ["meta"] = { ["fields"] = {  }, ["inventory"] = {  } }, ["param2"] = 0, ["y"] = 7, ["param1"] = 0, ["z"] = 11, ["name"] = "lottmapgen:mordor_stone" }, { ["x"] = 6, ["meta"] = { ["fields"] = {  }, ["inventory"] = {  } }, ["param2"] = 0, ["y"] = 7, ["param1"] = 136, ["z"] = 12, ["name"] = "lottother:air" }, { ["x"] = 6, ["meta"] = { ["fields"] = {  }, ["inventory"] = {  } }, ["param2"] = 0, ["y"] = 7, ["param1"] = 153, ["z"] = 13, ["name"] = "lottother:air" }, { ["x"] = 6, ["meta"] = { ["fields"] = {  }, ["inventory"] = {  } }, ["param2"] = 0, ["y"] = 7, ["param1"] = 170, ["z"] = 14, ["name"] = "lottother:air" }, { ["x"] = 6, ["meta"] = { ["fields"] = {  }, ["inventory"] = {  } }, ["param2"] = 0, ["y"] = 7, ["param1"] = 153, ["z"] = 15, ["name"] = "lottother:air" }, { ["x"] = 6, ["meta"] = { ["fields"] = {  }, ["inventory"] = {  } }, ["param2"] = 0, ["y"] = 7, ["param1"] = 136, ["z"] = 16, ["name"] = "lottother:air" }, { ["x"] = 6, ["meta"] = { ["fields"] = {  }, ["inventory"] = {  } }, ["param2"] = 0, ["y"] = 7, ["param1"] = 0, ["z"] = 17, ["name"] = "lottmapgen:mordor_stone" }, { ["x"] = 6, ["meta"] = { ["fields"] = {  }, ["inventory"] = {  } }, ["param2"] = 0, ["y"] = 7, ["param1"] = 0, ["z"] = 18, ["name"] = "lottmapgen:mordor_stone" }, { ["x"] = 6, ["meta"] = { ["fields"] = {  }, ["inventory"] = {  } }, ["param2"] = 0, ["y"] = 7, ["param1"] = 0, ["z"] = 19, ["name"] = "lottmapgen:mordor_stone" }, { ["x"] = 6, ["meta"] = { ["fields"] = {  }, ["inventory"] = {  } }, ["param2"] = 0, ["y"] = 8, ["param1"] = 0, ["z"] = 9, ["name"] = "lottmapgen:mordor_stone" }, { ["x"] = 6, ["meta"] = { ["fields"] = {  }, ["inventory"] = {  } }, ["param2"] = 0, ["y"] = 8, ["param1"] = 0, ["z"] = 10, ["name"] = "lottmapgen:mordor_stone" }, { ["x"] = 6, ["meta"] = { ["fields"] = {  }, ["inventory"] = {  } }, ["param2"] = 0, ["y"] = 8, ["param1"] = 0, ["z"] = 11, ["name"] = "lottmapgen:mordor_stone" }, { ["x"] = 6, ["meta"] = { ["fields"] = {  }, ["inventory"] = {  } }, ["param2"] = 0, ["y"] = 8, ["param1"] = 119, ["z"] = 12, ["name"] = "lottother:air" }, { ["x"] = 6, ["meta"] = { ["fields"] = {  }, ["inventory"] = {  } }, ["param2"] = 0, ["y"] = 8, ["param1"] = 136, ["z"] = 13, ["name"] = "lottother:air" }, { ["x"] = 6, ["meta"] = { ["fields"] = {  }, ["inventory"] = {  } }, ["param2"] = 0, ["y"] = 8, ["param1"] = 153, ["z"] = 14, ["name"] = "lottother:air" }, { ["x"] = 6, ["meta"] = { ["fields"] = {  }, ["inventory"] = {  } }, ["param2"] = 0, ["y"] = 8, ["param1"] = 136, ["z"] = 15, ["name"] = "lottother:air" }, { ["x"] = 6, ["meta"] = { ["fields"] = {  }, ["inventory"] = {  } }, ["param2"] = 0, ["y"] = 8, ["param1"] = 119, ["z"] = 16, ["name"] = "lottother:air" }, { ["x"] = 6, ["meta"] = { ["fields"] = {  }, ["inventory"] = {  } }, ["param2"] = 0, ["y"] = 8, ["param1"] = 0, ["z"] = 17, ["name"] = "lottmapgen:mordor_stone" }, { ["x"] = 6, ["meta"] = { ["fields"] = {  }, ["inventory"] = {  } }, ["param2"] = 0, ["y"] = 8, ["param1"] = 0, ["z"] = 18, ["name"] = "lottmapgen:mordor_stone" }, { ["x"] = 6, ["meta"] = { ["fields"] = {  }, ["inventory"] = {  } }, ["param2"] = 0, ["y"] = 8, ["param1"] = 0, ["z"] = 19, ["name"] = "lottmapgen:mordor_stone" }, { ["x"] = 6, ["meta"] = { ["fields"] = {  }, ["inventory"] = {  } }, ["param2"] = 0, ["y"] = 9, ["param1"] = 0, ["z"] = 9, ["name"] = "lottmapgen:mordor_stone" }, { ["x"] = 6, ["meta"] = { ["fields"] = {  }, ["inventory"] = {  } }, ["param2"] = 0, ["y"] = 9, ["param1"] = 0, ["z"] = 10, ["name"] = "lottmapgen:mordor_stone" }, { ["x"] = 6, ["meta"] = { ["fields"] = {  }, ["inventory"] = {  } }, ["param2"] = 0, ["y"] = 9, ["param1"] = 0, ["z"] = 11, ["name"] = "lottmapgen:mordor_stone" }, { ["x"] = 6, ["meta"] = { ["fields"] = {  }, ["inventory"] = {  } }, ["param2"] = 0, ["y"] = 9, ["param1"] = 102, ["z"] = 12, ["name"] = "lottother:air" }, { ["x"] = 6, ["meta"] = { ["fields"] = {  }, ["inventory"] = {  } }, ["param2"] = 0, ["y"] = 9, ["param1"] = 119, ["z"] = 13, ["name"] = "lottother:air" }, { ["x"] = 6, ["meta"] = { ["fields"] = {  }, ["inventory"] = {  } }, ["param2"] = 0, ["y"] = 9, ["param1"] = 136, ["z"] = 14, ["name"] = "lottother:air" }, { ["x"] = 6, ["meta"] = { ["fields"] = {  }, ["inventory"] = {  } }, ["param2"] = 0, ["y"] = 9, ["param1"] = 119, ["z"] = 15, ["name"] = "lottother:air" }, { ["x"] = 6, ["meta"] = { ["fields"] = {  }, ["inventory"] = {  } }, ["param2"] = 0, ["y"] = 9, ["param1"] = 102, ["z"] = 16, ["name"] = "lottother:air" }, { ["x"] = 6, ["meta"] = { ["fields"] = {  }, ["inventory"] = {  } }, ["param2"] = 0, ["y"] = 9, ["param1"] = 0, ["z"] = 17, ["name"] = "lottmapgen:mordor_stone" }, { ["x"] = 6, ["meta"] = { ["fields"] = {  }, ["inventory"] = {  } }, ["param2"] = 0, ["y"] = 9, ["param1"] = 0, ["z"] = 18, ["name"] = "lottmapgen:mordor_stone" }, { ["x"] = 6, ["meta"] = { ["fields"] = {  }, ["inventory"] = {  } }, ["param2"] = 0, ["y"] = 9, ["param1"] = 0, ["z"] = 19, ["name"] = "lottmapgen:mordor_stone" }, { ["x"] = 6, ["meta"] = { ["fields"] = {  }, ["inventory"] = {  } }, ["param2"] = 0, ["y"] = 10, ["param1"] = 0, ["z"] = 9, ["name"] = "lottmapgen:mordor_stone" }, { ["x"] = 6, ["meta"] = { ["fields"] = {  }, ["inventory"] = {  } }, ["param2"] = 0, ["y"] = 10, ["param1"] = 0, ["z"] = 10, ["name"] = "lottmapgen:mordor_stone" }, { ["x"] = 6, ["meta"] = { ["fields"] = {  }, ["inventory"] = {  } }, ["param2"] = 0, ["y"] = 10, ["param1"] = 0, ["z"] = 11, ["name"] = "lottmapgen:mordor_stone" }, { ["x"] = 6, ["meta"] = { ["fields"] = {  }, ["inventory"] = {  } }, ["param2"] = 0, ["y"] = 10, ["param1"] = 85, ["z"] = 12, ["name"] = "lottother:air" }, { ["x"] = 6, ["meta"] = { ["fields"] = {  }, ["inventory"] = {  } }, ["param2"] = 0, ["y"] = 10, ["param1"] = 102, ["z"] = 13, ["name"] = "lottother:air" }, { ["x"] = 6, ["meta"] = { ["fields"] = {  }, ["inventory"] = {  } }, ["param2"] = 0, ["y"] = 10, ["param1"] = 119, ["z"] = 14, ["name"] = "lottother:air" }, { ["x"] = 6, ["meta"] = { ["fields"] = {  }, ["inventory"] = {  } }, ["param2"] = 0, ["y"] = 10, ["param1"] = 102, ["z"] = 15, ["name"] = "lottother:air" }, { ["x"] = 6, ["meta"] = { ["fields"] = {  }, ["inventory"] = {  } }, ["param2"] = 0, ["y"] = 10, ["param1"] = 85, ["z"] = 16, ["name"] = "lottother:air" }, { ["x"] = 6, ["meta"] = { ["fields"] = {  }, ["inventory"] = {  } }, ["param2"] = 0, ["y"] = 10, ["param1"] = 0, ["z"] = 17, ["name"] = "lottmapgen:mordor_stone" }, { ["x"] = 6, ["meta"] = { ["fields"] = {  }, ["inventory"] = {  } }, ["param2"] = 0, ["y"] = 10, ["param1"] = 0, ["z"] = 18, ["name"] = "lottmapgen:mordor_stone" }, { ["x"] = 6, ["meta"] = { ["fields"] = {  }, ["inventory"] = {  } }, ["param2"] = 0, ["y"] = 10, ["param1"] = 0, ["z"] = 19, ["name"] = "lottmapgen:mordor_stone" }, { ["x"] = 6, ["meta"] = { ["fields"] = {  }, ["inventory"] = {  } }, ["param2"] = 0, ["y"] = 11, ["param1"] = 0, ["z"] = 9, ["name"] = "lottmapgen:mordor_stone" }, { ["x"] = 6, ["meta"] = { ["fields"] = {  }, ["inventory"] = {  } }, ["param2"] = 0, ["y"] = 11, ["param1"] = 0, ["z"] = 10, ["name"] = "lottmapgen:mordor_stone" }, { ["x"] = 6, ["meta"] = { ["fields"] = {  }, ["inventory"] = {  } }, ["param2"] = 0, ["y"] = 11, ["param1"] = 0, ["z"] = 11, ["name"] = "lottmapgen:mordor_stone" }, { ["x"] = 6, ["meta"] = { ["fields"] = {  }, ["inventory"] = {  } }, ["param2"] = 0, ["y"] = 11, ["param1"] = 68, ["z"] = 12, ["name"] = "lottother:air" }, { ["x"] = 6, ["meta"] = { ["fields"] = {  }, ["inventory"] = {  } }, ["param2"] = 0, ["y"] = 11, ["param1"] = 85, ["z"] = 13, ["name"] = "lottother:air" }, { ["x"] = 6, ["meta"] = { ["fields"] = {  }, ["inventory"] = {  } }, ["param2"] = 0, ["y"] = 11, ["param1"] = 102, ["z"] = 14, ["name"] = "lottother:air" }, { ["x"] = 6, ["meta"] = { ["fields"] = {  }, ["inventory"] = {  } }, ["param2"] = 0, ["y"] = 11, ["param1"] = 85, ["z"] = 15, ["name"] = "lottother:air" }, { ["x"] = 6, ["meta"] = { ["fields"] = {  }, ["inventory"] = {  } }, ["param2"] = 0, ["y"] = 11, ["param1"] = 68, ["z"] = 16, ["name"] = "lottother:air" }, { ["x"] = 6, ["meta"] = { ["fields"] = {  }, ["inventory"] = {  } }, ["param2"] = 0, ["y"] = 11, ["param1"] = 0, ["z"] = 17, ["name"] = "lottmapgen:mordor_stone" }, { ["x"] = 6, ["meta"] = { ["fields"] = {  }, ["inventory"] = {  } }, ["param2"] = 0, ["y"] = 11, ["param1"] = 0, ["z"] = 18, ["name"] = "lottmapgen:mordor_stone" }, { ["x"] = 6, ["meta"] = { ["fields"] = {  }, ["inventory"] = {  } }, ["param2"] = 0, ["y"] = 11, ["param1"] = 0, ["z"] = 19, ["name"] = "lottmapgen:mordor_stone" }, { ["x"] = 6, ["meta"] = { ["fields"] = {  }, ["inventory"] = {  } }, ["param2"] = 0, ["y"] = 12, ["param1"] = 0, ["z"] = 9, ["name"] = "lottmapgen:mordor_stone" }, { ["x"] = 6, ["meta"] = { ["fields"] = {  }, ["inventory"] = {  } }, ["param2"] = 0, ["y"] = 12, ["param1"] = 0, ["z"] = 10, ["name"] = "lottmapgen:mordor_stone" }, { ["x"] = 6, ["meta"] = { ["fields"] = {  }, ["inventory"] = {  } }, ["param2"] = 0, ["y"] = 12, ["param1"] = 0, ["z"] = 11, ["name"] = "lottmapgen:mordor_stone" }, { ["x"] = 6, ["meta"] = { ["fields"] = {  }, ["inventory"] = {  } }, ["param2"] = 0, ["y"] = 12, ["param1"] = 0, ["z"] = 12, ["name"] = "lottmapgen:mordor_stone" }, { ["x"] = 6, ["meta"] = { ["fields"] = {  }, ["inventory"] = {  } }, ["param2"] = 0, ["y"] = 12, ["param1"] = 0, ["z"] = 13, ["name"] = "lottmapgen:mordor_stone" }, { ["x"] = 6, ["meta"] = { ["fields"] = {  }, ["inventory"] = {  } }, ["param2"] = 0, ["y"] = 12, ["param1"] = 0, ["z"] = 14, ["name"] = "lottmapgen:mordor_stone" }, { ["x"] = 6, ["meta"] = { ["fields"] = {  }, ["inventory"] = {  } }, ["param2"] = 0, ["y"] = 12, ["param1"] = 0, ["z"] = 15, ["name"] = "lottmapgen:mordor_stone" }, { ["x"] = 6, ["meta"] = { ["fields"] = {  }, ["inventory"] = {  } }, ["param2"] = 0, ["y"] = 12, ["param1"] = 0, ["z"] = 16, ["name"] = "lottmapgen:mordor_stone" }, { ["x"] = 6, ["meta"] = { ["fields"] = {  }, ["inventory"] = {  } }, ["param2"] = 0, ["y"] = 12, ["param1"] = 0, ["z"] = 17, ["name"] = "lottmapgen:mordor_stone" }, { ["x"] = 6, ["meta"] = { ["fields"] = {  }, ["inventory"] = {  } }, ["param2"] = 0, ["y"] = 12, ["param1"] = 0, ["z"] = 18, ["name"] = "lottmapgen:mordor_stone" }, { ["x"] = 6, ["meta"] = { ["fields"] = {  }, ["inventory"] = {  } }, ["param2"] = 0, ["y"] = 12, ["param1"] = 0, ["z"] = 19, ["name"] = "lottmapgen:mordor_stone" }, { ["x"] = 6, ["meta"] = { ["fields"] = {  }, ["inventory"] = {  } }, ["param2"] = 0, ["y"] = 13, ["param1"] = 0, ["z"] = 8, ["name"] = "lottmapgen:mordor_stone" }, { ["x"] = 6, ["meta"] = { ["fields"] = {  }, ["inventory"] = {  } }, ["param2"] = 0, ["y"] = 13, ["param1"] = 15, ["z"] = 9, ["name"] = "lottother:air" }, { ["x"] = 6, ["meta"] = { ["fields"] = {  }, ["inventory"] = {  } }, ["param2"] = 0, ["y"] = 13, ["param1"] = 15, ["z"] = 10, ["name"] = "lottother:air" }, { ["x"] = 6, ["meta"] = { ["fields"] = {  }, ["inventory"] = {  } }, ["param2"] = 0, ["y"] = 13, ["param1"] = 15, ["z"] = 11, ["name"] = "lottother:air" }, { ["x"] = 6, ["meta"] = { ["fields"] = {  }, ["inventory"] = {  } }, ["param2"] = 0, ["y"] = 13, ["param1"] = 31, ["z"] = 12, ["name"] = "lottother:air" }, { ["x"] = 6, ["meta"] = { ["fields"] = {  }, ["inventory"] = {  } }, ["param2"] = 0, ["y"] = 13, ["param1"] = 47, ["z"] = 13, ["name"] = "lottother:air" }, { ["x"] = 6, ["meta"] = { ["fields"] = {  }, ["inventory"] = {  } }, ["param2"] = 0, ["y"] = 13, ["param1"] = 63, ["z"] = 14, ["name"] = "lottother:air" }, { ["x"] = 6, ["meta"] = { ["fields"] = {  }, ["inventory"] = {  } }, ["param2"] = 0, ["y"] = 13, ["param1"] = 47, ["z"] = 15, ["name"] = "lottother:air" }, { ["x"] = 6, ["meta"] = { ["fields"] = {  }, ["inventory"] = {  } }, ["param2"] = 0, ["y"] = 13, ["param1"] = 31, ["z"] = 16, ["name"] = "lottother:air" }, { ["x"] = 6, ["meta"] = { ["fields"] = {  }, ["inventory"] = {  } }, ["param2"] = 0, ["y"] = 13, ["param1"] = 15, ["z"] = 17, ["name"] = "lottother:air" }, { ["x"] = 6, ["meta"] = { ["fields"] = {  }, ["inventory"] = {  } }, ["param2"] = 0, ["y"] = 13, ["param1"] = 15, ["z"] = 18, ["name"] = "lottother:air" }, { ["x"] = 6, ["meta"] = { ["fields"] = {  }, ["inventory"] = {  } }, ["param2"] = 0, ["y"] = 13, ["param1"] = 15, ["z"] = 19, ["name"] = "lottother:air" }, { ["x"] = 6, ["meta"] = { ["fields"] = {  }, ["inventory"] = {  } }, ["param2"] = 0, ["y"] = 13, ["param1"] = 0, ["z"] = 20, ["name"] = "lottmapgen:mordor_stone" }, { ["x"] = 6, ["meta"] = { ["fields"] = {  }, ["inventory"] = {  } }, ["param2"] = 0, ["y"] = 14, ["param1"] = 15, ["z"] = 8, ["name"] = "lottother:air" }, { ["x"] = 6, ["meta"] = { ["fields"] = {  }, ["inventory"] = {  } }, ["param2"] = 0, ["y"] = 14, ["param1"] = 15, ["z"] = 9, ["name"] = "lottother:air" }, { ["x"] = 6, ["meta"] = { ["fields"] = {  }, ["inventory"] = {  } }, ["param2"] = 0, ["y"] = 14, ["param1"] = 15, ["z"] = 10, ["name"] = "lottother:air" }, { ["x"] = 6, ["meta"] = { ["fields"] = {  }, ["inventory"] = {  } }, ["param2"] = 0, ["y"] = 14, ["param1"] = 31, ["z"] = 11, ["name"] = "lottother:air" }, { ["x"] = 6, ["meta"] = { ["fields"] = {  }, ["inventory"] = {  } }, ["param2"] = 0, ["y"] = 14, ["param1"] = 47, ["z"] = 12, ["name"] = "lottother:air" }, { ["x"] = 6, ["meta"] = { ["fields"] = {  }, ["inventory"] = {  } }, ["param2"] = 0, ["y"] = 14, ["param1"] = 63, ["z"] = 13, ["name"] = "lottother:air" }, { ["x"] = 6, ["meta"] = { ["fields"] = {  }, ["inventory"] = {  } }, ["param2"] = 0, ["y"] = 14, ["param1"] = 79, ["z"] = 14, ["name"] = "lottother:air" }, { ["x"] = 6, ["meta"] = { ["fields"] = {  }, ["inventory"] = {  } }, ["param2"] = 0, ["y"] = 14, ["param1"] = 63, ["z"] = 15, ["name"] = "lottother:air" }, { ["x"] = 6, ["meta"] = { ["fields"] = {  }, ["inventory"] = {  } }, ["param2"] = 0, ["y"] = 14, ["param1"] = 47, ["z"] = 16, ["name"] = "lottother:air" }, { ["x"] = 6, ["meta"] = { ["fields"] = {  }, ["inventory"] = {  } }, ["param2"] = 0, ["y"] = 14, ["param1"] = 31, ["z"] = 17, ["name"] = "lottother:air" }, { ["x"] = 6, ["meta"] = { ["fields"] = {  }, ["inventory"] = {  } }, ["param2"] = 0, ["y"] = 14, ["param1"] = 15, ["z"] = 18, ["name"] = "lottother:air" }, { ["x"] = 6, ["meta"] = { ["fields"] = {  }, ["inventory"] = {  } }, ["param2"] = 0, ["y"] = 14, ["param1"] = 15, ["z"] = 19, ["name"] = "lottother:air" }, { ["x"] = 6, ["meta"] = { ["fields"] = {  }, ["inventory"] = {  } }, ["param2"] = 0, ["y"] = 14, ["param1"] = 15, ["z"] = 20, ["name"] = "lottother:air" }, { ["x"] = 6, ["meta"] = { ["fields"] = {  }, ["inventory"] = {  } }, ["param2"] = 0, ["y"] = 15, ["param1"] = 15, ["z"] = 8, ["name"] = "lottother:air" }, { ["x"] = 6, ["meta"] = { ["fields"] = {  }, ["inventory"] = {  } }, ["param2"] = 0, ["y"] = 15, ["param1"] = 15, ["z"] = 9, ["name"] = "lottother:air" }, { ["x"] = 6, ["meta"] = { ["fields"] = {  }, ["inventory"] = {  } }, ["param2"] = 0, ["y"] = 15, ["param1"] = 31, ["z"] = 10, ["name"] = "lottother:air" }, { ["x"] = 6, ["meta"] = { ["fields"] = {  }, ["inventory"] = {  } }, ["param2"] = 0, ["y"] = 15, ["param1"] = 47, ["z"] = 11, ["name"] = "lottother:air" }, { ["x"] = 6, ["meta"] = { ["fields"] = {  }, ["inventory"] = {  } }, ["param2"] = 0, ["y"] = 15, ["param1"] = 63, ["z"] = 12, ["name"] = "lottother:air" }, { ["x"] = 6, ["meta"] = { ["fields"] = {  }, ["inventory"] = {  } }, ["param2"] = 0, ["y"] = 15, ["param1"] = 79, ["z"] = 13, ["name"] = "lottother:air" }, { ["x"] = 6, ["meta"] = { ["fields"] = {  }, ["inventory"] = {  } }, ["param2"] = 0, ["y"] = 15, ["param1"] = 95, ["z"] = 14, ["name"] = "lottother:air" }, { ["x"] = 6, ["meta"] = { ["fields"] = {  }, ["inventory"] = {  } }, ["param2"] = 0, ["y"] = 15, ["param1"] = 79, ["z"] = 15, ["name"] = "lottother:air" }, { ["x"] = 6, ["meta"] = { ["fields"] = {  }, ["inventory"] = {  } }, ["param2"] = 0, ["y"] = 15, ["param1"] = 63, ["z"] = 16, ["name"] = "lottother:air" }, { ["x"] = 6, ["meta"] = { ["fields"] = {  }, ["inventory"] = {  } }, ["param2"] = 0, ["y"] = 15, ["param1"] = 47, ["z"] = 17, ["name"] = "lottother:air" }, { ["x"] = 6, ["meta"] = { ["fields"] = {  }, ["inventory"] = {  } }, ["param2"] = 0, ["y"] = 15, ["param1"] = 31, ["z"] = 18, ["name"] = "lottother:air" }, { ["x"] = 6, ["meta"] = { ["fields"] = {  }, ["inventory"] = {  } }, ["param2"] = 0, ["y"] = 15, ["param1"] = 15, ["z"] = 19, ["name"] = "lottother:air" }, { ["x"] = 6, ["meta"] = { ["fields"] = {  }, ["inventory"] = {  } }, ["param2"] = 0, ["y"] = 15, ["param1"] = 15, ["z"] = 20, ["name"] = "lottother:air" }, { ["x"] = 7, ["meta"] = { ["fields"] = {  }, ["inventory"] = {  } }, ["param2"] = 0, ["y"] = 0, ["param1"] = 0, ["z"] = 4, ["name"] = "lottother:mordor_stone" }, { ["x"] = 7, ["meta"] = { ["fields"] = {  }, ["inventory"] = {  } }, ["param2"] = 0, ["y"] = 0, ["param1"] = 0, ["z"] = 5, ["name"] = "lottother:mordor_stone" }, { ["x"] = 7, ["meta"] = { ["fields"] = {  }, ["inventory"] = {  } }, ["param2"] = 0, ["y"] = 0, ["param1"] = 15, ["z"] = 6, ["name"] = "lottother:mordor_stone" }, { ["x"] = 7, ["meta"] = { ["fields"] = {  }, ["inventory"] = {  } }, ["param2"] = 0, ["y"] = 0, ["param1"] = 13, ["z"] = 7, ["name"] = "lottother:mordor_stone" }, { ["x"] = 7, ["meta"] = { ["fields"] = {  }, ["inventory"] = {  } }, ["param2"] = 0, ["y"] = 0, ["param1"] = 12, ["z"] = 8, ["name"] = "lottother:mordor_stone" }, { ["x"] = 7, ["meta"] = { ["fields"] = {  }, ["inventory"] = {  } }, ["param2"] = 0, ["y"] = 0, ["param1"] = 11, ["z"] = 9, ["name"] = "lottother:mordor_stone" }, { ["x"] = 7, ["meta"] = { ["fields"] = {  }, ["inventory"] = {  } }, ["param2"] = 0, ["y"] = 0, ["param1"] = 10, ["z"] = 10, ["name"] = "lottother:mordor_stone" }, { ["x"] = 7, ["meta"] = { ["fields"] = {  }, ["inventory"] = {  } }, ["param2"] = 0, ["y"] = 0, ["param1"] = 10, ["z"] = 11, ["name"] = "lottother:mordor_stone" }, { ["x"] = 7, ["meta"] = { ["fields"] = {  }, ["inventory"] = {  } }, ["param2"] = 0, ["y"] = 0, ["param1"] = 10, ["z"] = 12, ["name"] = "lottother:mordor_stone" }, { ["x"] = 7, ["meta"] = { ["fields"] = {  }, ["inventory"] = {  } }, ["param2"] = 0, ["y"] = 0, ["param1"] = 9, ["z"] = 13, ["name"] = "lottother:mordor_stone" }, { ["x"] = 7, ["meta"] = { ["fields"] = {  }, ["inventory"] = {  } }, ["param2"] = 0, ["y"] = 0, ["param1"] = 8, ["z"] = 14, ["name"] = "lottother:mordor_stone" }, { ["x"] = 7, ["meta"] = { ["fields"] = {  }, ["inventory"] = {  } }, ["param2"] = 0, ["y"] = 0, ["param1"] = 9, ["z"] = 15, ["name"] = "lottother:mordor_stone" }, { ["x"] = 7, ["meta"] = { ["fields"] = {  }, ["inventory"] = {  } }, ["param2"] = 0, ["y"] = 0, ["param1"] = 10, ["z"] = 16, ["name"] = "lottother:mordor_stone" }, { ["x"] = 7, ["meta"] = { ["fields"] = {  }, ["inventory"] = {  } }, ["param2"] = 0, ["y"] = 0, ["param1"] = 10, ["z"] = 17, ["name"] = "lottother:mordor_stone" }, { ["x"] = 7, ["meta"] = { ["fields"] = {  }, ["inventory"] = {  } }, ["param2"] = 0, ["y"] = 0, ["param1"] = 10, ["z"] = 18, ["name"] = "lottother:mordor_stone" }, { ["x"] = 7, ["meta"] = { ["fields"] = {  }, ["inventory"] = {  } }, ["param2"] = 0, ["y"] = 0, ["param1"] = 11, ["z"] = 19, ["name"] = "lottother:mordor_stone" }, { ["x"] = 7, ["meta"] = { ["fields"] = {  }, ["inventory"] = {  } }, ["param2"] = 0, ["y"] = 0, ["param1"] = 12, ["z"] = 20, ["name"] = "lottother:mordor_stone" }, { ["x"] = 7, ["meta"] = { ["fields"] = {  }, ["inventory"] = {  } }, ["param2"] = 0, ["y"] = 0, ["param1"] = 13, ["z"] = 21, ["name"] = "lottother:mordor_stone" }, { ["x"] = 7, ["meta"] = { ["fields"] = {  }, ["inventory"] = {  } }, ["param2"] = 0, ["y"] = 0, ["param1"] = 15, ["z"] = 22, ["name"] = "lottother:mordor_stone" }, { ["x"] = 7, ["meta"] = { ["fields"] = {  }, ["inventory"] = {  } }, ["param2"] = 0, ["y"] = 0, ["param1"] = 0, ["z"] = 23, ["name"] = "lottother:mordor_stone" }, { ["x"] = 7, ["meta"] = { ["fields"] = {  }, ["inventory"] = {  } }, ["param2"] = 0, ["y"] = 0, ["param1"] = 0, ["z"] = 24, ["name"] = "lottother:mordor_stone" }, { ["x"] = 7, ["meta"] = { ["fields"] = {  }, ["inventory"] = {  } }, ["param2"] = 0, ["y"] = 1, ["param1"] = 15, ["z"] = 6, ["name"] = "lottother:mordor_stone" }, { ["x"] = 7, ["meta"] = { ["fields"] = {  }, ["inventory"] = {  } }, ["param2"] = 0, ["y"] = 1, ["param1"] = 13, ["z"] = 7, ["name"] = "lottother:mordor_stone" }, { ["x"] = 7, ["meta"] = { ["fields"] = {  }, ["inventory"] = {  } }, ["param2"] = 0, ["y"] = 1, ["param1"] = 12, ["z"] = 8, ["name"] = "lottother:mordor_stone" }, { ["x"] = 7, ["meta"] = { ["fields"] = {  }, ["inventory"] = {  } }, ["param2"] = 0, ["y"] = 1, ["param1"] = 11, ["z"] = 9, ["name"] = "lottother:mordor_stone" }, { ["x"] = 7, ["meta"] = { ["fields"] = {  }, ["inventory"] = {  } }, ["param2"] = 0, ["y"] = 1, ["param1"] = 10, ["z"] = 10, ["name"] = "lottother:mordor_stone" }, { ["x"] = 7, ["meta"] = { ["fields"] = {  }, ["inventory"] = {  } }, ["param2"] = 0, ["y"] = 1, ["param1"] = 10, ["z"] = 11, ["name"] = "lottother:mordor_stone" }, { ["x"] = 7, ["meta"] = { ["fields"] = {  }, ["inventory"] = {  } }, ["param2"] = 0, ["y"] = 1, ["param1"] = 10, ["z"] = 12, ["name"] = "lottother:mordor_stone" }, { ["x"] = 7, ["meta"] = { ["fields"] = {  }, ["inventory"] = {  } }, ["param2"] = 0, ["y"] = 1, ["param1"] = 9, ["z"] = 13, ["name"] = "lottother:mordor_stone" }, { ["x"] = 7, ["meta"] = { ["fields"] = {  }, ["inventory"] = {  } }, ["param2"] = 0, ["y"] = 1, ["param1"] = 8, ["z"] = 14, ["name"] = "lottother:mordor_stone" }, { ["x"] = 7, ["meta"] = { ["fields"] = {  }, ["inventory"] = {  } }, ["param2"] = 0, ["y"] = 1, ["param1"] = 9, ["z"] = 15, ["name"] = "lottother:mordor_stone" }, { ["x"] = 7, ["meta"] = { ["fields"] = {  }, ["inventory"] = {  } }, ["param2"] = 0, ["y"] = 1, ["param1"] = 10, ["z"] = 16, ["name"] = "lottother:mordor_stone" }, { ["x"] = 7, ["meta"] = { ["fields"] = {  }, ["inventory"] = {  } }, ["param2"] = 0, ["y"] = 1, ["param1"] = 10, ["z"] = 17, ["name"] = "lottother:mordor_stone" }, { ["x"] = 7, ["meta"] = { ["fields"] = {  }, ["inventory"] = {  } }, ["param2"] = 0, ["y"] = 1, ["param1"] = 10, ["z"] = 18, ["name"] = "lottother:mordor_stone" }, { ["x"] = 7, ["meta"] = { ["fields"] = {  }, ["inventory"] = {  } }, ["param2"] = 0, ["y"] = 1, ["param1"] = 11, ["z"] = 19, ["name"] = "lottother:mordor_stone" }, { ["x"] = 7, ["meta"] = { ["fields"] = {  }, ["inventory"] = {  } }, ["param2"] = 0, ["y"] = 1, ["param1"] = 12, ["z"] = 20, ["name"] = "lottother:mordor_stone" }, { ["x"] = 7, ["meta"] = { ["fields"] = {  }, ["inventory"] = {  } }, ["param2"] = 0, ["y"] = 1, ["param1"] = 13, ["z"] = 21, ["name"] = "lottother:mordor_stone" }, { ["x"] = 7, ["meta"] = { ["fields"] = {  }, ["inventory"] = {  } }, ["param2"] = 0, ["y"] = 1, ["param1"] = 15, ["z"] = 22, ["name"] = "lottother:mordor_stone" }, { ["x"] = 7, ["meta"] = { ["fields"] = {  }, ["inventory"] = {  } }, ["param2"] = 0, ["y"] = 2, ["param1"] = 0, ["z"] = 8, ["name"] = "lottmapgen:mordor_stone" }, { ["x"] = 7, ["meta"] = { ["fields"] = {  }, ["inventory"] = {  } }, ["param2"] = 0, ["y"] = 2, ["param1"] = 0, ["z"] = 9, ["name"] = "lottmapgen:mordor_stone" }, { ["x"] = 7, ["meta"] = { ["fields"] = {  }, ["inventory"] = {  } }, ["param2"] = 0, ["y"] = 2, ["param1"] = 0, ["z"] = 10, ["name"] = "lottmapgen:mordor_stone" }, { ["x"] = 7, ["meta"] = { ["fields"] = {  }, ["inventory"] = {  } }, ["param2"] = 0, ["y"] = 2, ["param1"] = 0, ["z"] = 11, ["name"] = "lottmapgen:mordor_stone" }, { ["x"] = 7, ["meta"] = { ["fields"] = {  }, ["inventory"] = {  } }, ["param2"] = 0, ["y"] = 2, ["param1"] = 0, ["z"] = 12, ["name"] = "lottmapgen:mordor_stone" }, { ["x"] = 7, ["meta"] = { ["fields"] = {  }, ["inventory"] = {  } }, ["param2"] = 0, ["y"] = 2, ["param1"] = 0, ["z"] = 13, ["name"] = "lottmapgen:mordor_stone" }, { ["x"] = 7, ["meta"] = { ["fields"] = {  }, ["inventory"] = {  } }, ["param2"] = 0, ["y"] = 2, ["param1"] = 0, ["z"] = 14, ["name"] = "lottblocks:orc_brick" }, { ["x"] = 7, ["meta"] = { ["fields"] = {  }, ["inventory"] = {  } }, ["param2"] = 0, ["y"] = 2, ["param1"] = 0, ["z"] = 15, ["name"] = "lottmapgen:mordor_stone" }, { ["x"] = 7, ["meta"] = { ["fields"] = {  }, ["inventory"] = {  } }, ["param2"] = 0, ["y"] = 2, ["param1"] = 0, ["z"] = 16, ["name"] = "lottmapgen:mordor_stone" }, { ["x"] = 7, ["meta"] = { ["fields"] = {  }, ["inventory"] = {  } }, ["param2"] = 0, ["y"] = 2, ["param1"] = 0, ["z"] = 17, ["name"] = "lottmapgen:mordor_stone" }, { ["x"] = 7, ["meta"] = { ["fields"] = {  }, ["inventory"] = {  } }, ["param2"] = 0, ["y"] = 2, ["param1"] = 0, ["z"] = 18, ["name"] = "lottmapgen:mordor_stone" }, { ["x"] = 7, ["meta"] = { ["fields"] = {  }, ["inventory"] = {  } }, ["param2"] = 0, ["y"] = 2, ["param1"] = 0, ["z"] = 19, ["name"] = "lottmapgen:mordor_stone" }, { ["x"] = 7, ["meta"] = { ["fields"] = {  }, ["inventory"] = {  } }, ["param2"] = 0, ["y"] = 2, ["param1"] = 0, ["z"] = 20, ["name"] = "lottmapgen:mordor_stone" }, { ["x"] = 7, ["meta"] = { ["fields"] = {  }, ["inventory"] = {  } }, ["param2"] = 0, ["y"] = 3, ["param1"] = 0, ["z"] = 8, ["name"] = "lottmapgen:mordor_stone" }, { ["x"] = 7, ["meta"] = { ["fields"] = {  }, ["inventory"] = {  } }, ["param2"] = 0, ["y"] = 3, ["param1"] = 102, ["z"] = 9, ["name"] = "lottother:air" }, { ["x"] = 7, ["meta"] = { ["fields"] = {  }, ["inventory"] = {  } }, ["param2"] = 0, ["y"] = 3, ["param1"] = 119, ["z"] = 10, ["name"] = "lottother:air" }, { ["x"] = 7, ["meta"] = { ["fields"] = {  }, ["inventory"] = {  } }, ["param2"] = 0, ["y"] = 3, ["param1"] = 136, ["z"] = 11, ["name"] = "lottother:air" }, { ["x"] = 7, ["meta"] = { ["fields"] = {  }, ["inventory"] = {  } }, ["param2"] = 0, ["y"] = 3, ["param1"] = 153, ["z"] = 12, ["name"] = "lottother:air" }, { ["x"] = 7, ["meta"] = { ["fields"] = {  }, ["inventory"] = {  } }, ["param2"] = 0, ["y"] = 3, ["param1"] = 170, ["z"] = 13, ["name"] = "lottother:air" }, { ["x"] = 7, ["meta"] = { ["fields"] = {  }, ["inventory"] = {  } }, ["param2"] = 0, ["y"] = 3, ["param1"] = 153, ["z"] = 14, ["name"] = "lottother:air" }, { ["x"] = 7, ["meta"] = { ["fields"] = {  }, ["inventory"] = {  } }, ["param2"] = 0, ["y"] = 3, ["param1"] = 170, ["z"] = 15, ["name"] = "stairs:stair_orc_brick" }, { ["x"] = 7, ["meta"] = { ["fields"] = {  }, ["inventory"] = {  } }, ["param2"] = 0, ["y"] = 3, ["param1"] = 0, ["z"] = 16, ["name"] = "lottmapgen:mordor_stone" }, { ["x"] = 7, ["meta"] = { ["fields"] = {  }, ["inventory"] = {  } }, ["param2"] = 0, ["y"] = 3, ["param1"] = 0, ["z"] = 17, ["name"] = "lottmapgen:mordor_stone" }, { ["x"] = 7, ["meta"] = { ["fields"] = {  }, ["inventory"] = {  } }, ["param2"] = 0, ["y"] = 3, ["param1"] = 85, ["z"] = 18, ["name"] = "lottother:air" }, { ["x"] = 7, ["meta"] = { ["fields"] = {  }, ["inventory"] = {  } }, ["param2"] = 0, ["y"] = 3, ["param1"] = 68, ["z"] = 19, ["name"] = "lottother:air" }, { ["x"] = 7, ["meta"] = { ["fields"] = {  }, ["inventory"] = {  } }, ["param2"] = 0, ["y"] = 3, ["param1"] = 0, ["z"] = 20, ["name"] = "lottmapgen:mordor_stone" }, { ["x"] = 7, ["meta"] = { ["fields"] = {  }, ["inventory"] = {  } }, ["param2"] = 0, ["y"] = 4, ["param1"] = 0, ["z"] = 8, ["name"] = "lottmapgen:mordor_stone" }, { ["x"] = 7, ["meta"] = { ["fields"] = {  }, ["inventory"] = {  } }, ["param2"] = 0, ["y"] = 4, ["param1"] = 102, ["z"] = 9, ["name"] = "lottother:air" }, { ["x"] = 7, ["meta"] = { ["fields"] = {  }, ["inventory"] = {  } }, ["param2"] = 0, ["y"] = 4, ["param1"] = 119, ["z"] = 10, ["name"] = "lottother:air" }, { ["x"] = 7, ["meta"] = { ["fields"] = {  }, ["inventory"] = {  } }, ["param2"] = 0, ["y"] = 4, ["param1"] = 136, ["z"] = 11, ["name"] = "lottother:air" }, { ["x"] = 7, ["meta"] = { ["fields"] = {  }, ["inventory"] = {  } }, ["param2"] = 0, ["y"] = 4, ["param1"] = 153, ["z"] = 12, ["name"] = "lottother:air" }, { ["x"] = 7, ["meta"] = { ["fields"] = {  }, ["inventory"] = {  } }, ["param2"] = 0, ["y"] = 4, ["param1"] = 170, ["z"] = 13, ["name"] = "lottother:air" }, { ["x"] = 7, ["meta"] = { ["fields"] = {  }, ["inventory"] = {  } }, ["param2"] = 0, ["y"] = 4, ["param1"] = 153, ["z"] = 14, ["name"] = "lottother:air" }, { ["x"] = 7, ["meta"] = { ["fields"] = {  }, ["inventory"] = {  } }, ["param2"] = 0, ["y"] = 4, ["param1"] = 170, ["z"] = 15, ["name"] = "lottother:air" }, { ["x"] = 7, ["meta"] = { ["fields"] = {  }, ["inventory"] = {  } }, ["param2"] = 0, ["y"] = 4, ["param1"] = 153, ["z"] = 16, ["name"] = "stairs:stair_orc_brick" }, { ["x"] = 7, ["meta"] = { ["fields"] = {  }, ["inventory"] = {  } }, ["param2"] = 0, ["y"] = 4, ["param1"] = 0, ["z"] = 17, ["name"] = "lottmapgen:mordor_stone" }, { ["x"] = 7, ["meta"] = { ["fields"] = {  }, ["inventory"] = {  } }, ["param2"] = 0, ["y"] = 4, ["param1"] = 102, ["z"] = 18, ["name"] = "lottother:air" }, { ["x"] = 7, ["meta"] = { ["fields"] = {  }, ["inventory"] = {  } }, ["param2"] = 0, ["y"] = 4, ["param1"] = 85, ["z"] = 19, ["name"] = "lottother:air" }, { ["x"] = 7, ["meta"] = { ["fields"] = {  }, ["inventory"] = {  } }, ["param2"] = 0, ["y"] = 4, ["param1"] = 0, ["z"] = 20, ["name"] = "lottmapgen:mordor_stone" }, { ["x"] = 7, ["meta"] = { ["fields"] = {  }, ["inventory"] = {  } }, ["param2"] = 0, ["y"] = 5, ["param1"] = 0, ["z"] = 8, ["name"] = "lottmapgen:mordor_stone" }, { ["x"] = 7, ["meta"] = { ["fields"] = {  }, ["inventory"] = {  } }, ["param2"] = 0, ["y"] = 5, ["param1"] = 102, ["z"] = 9, ["name"] = "lottother:air" }, { ["x"] = 7, ["meta"] = { ["fields"] = {  }, ["inventory"] = {  } }, ["param2"] = 0, ["y"] = 5, ["param1"] = 119, ["z"] = 10, ["name"] = "lottother:air" }, { ["x"] = 7, ["meta"] = { ["fields"] = {  }, ["inventory"] = {  } }, ["param2"] = 0, ["y"] = 5, ["param1"] = 136, ["z"] = 11, ["name"] = "lottother:air" }, { ["x"] = 7, ["meta"] = { ["fields"] = {  }, ["inventory"] = {  } }, ["param2"] = 0, ["y"] = 5, ["param1"] = 153, ["z"] = 12, ["name"] = "lottother:air" }, { ["x"] = 7, ["meta"] = { ["fields"] = {  }, ["inventory"] = {  } }, ["param2"] = 0, ["y"] = 5, ["param1"] = 170, ["z"] = 13, ["name"] = "lottother:air" }, { ["x"] = 7, ["meta"] = { ["fields"] = {  }, ["inventory"] = {  } }, ["param2"] = 0, ["y"] = 5, ["param1"] = 153, ["z"] = 14, ["name"] = "lottother:air" }, { ["x"] = 7, ["meta"] = { ["fields"] = {  }, ["inventory"] = {  } }, ["param2"] = 0, ["y"] = 5, ["param1"] = 170, ["z"] = 15, ["name"] = "lottother:air" }, { ["x"] = 7, ["meta"] = { ["fields"] = {  }, ["inventory"] = {  } }, ["param2"] = 0, ["y"] = 5, ["param1"] = 153, ["z"] = 16, ["name"] = "lottother:air" }, { ["x"] = 7, ["meta"] = { ["fields"] = {  }, ["inventory"] = {  } }, ["param2"] = 0, ["y"] = 5, ["param1"] = 136, ["z"] = 17, ["name"] = "lottother:air" }, { ["x"] = 7, ["meta"] = { ["fields"] = {  }, ["inventory"] = {  } }, ["param2"] = 0, ["y"] = 5, ["param1"] = 119, ["z"] = 18, ["name"] = "lottother:air" }, { ["x"] = 7, ["meta"] = { ["fields"] = {  }, ["inventory"] = {  } }, ["param2"] = 0, ["y"] = 5, ["param1"] = 102, ["z"] = 19, ["name"] = "lottother:air" }, { ["x"] = 7, ["meta"] = { ["fields"] = {  }, ["inventory"] = {  } }, ["param2"] = 0, ["y"] = 5, ["param1"] = 0, ["z"] = 20, ["name"] = "lottmapgen:mordor_stone" }, { ["x"] = 7, ["meta"] = { ["fields"] = {  }, ["inventory"] = {  } }, ["param2"] = 0, ["y"] = 6, ["param1"] = 0, ["z"] = 8, ["name"] = "lottmapgen:mordor_stone" }, { ["x"] = 7, ["meta"] = { ["fields"] = {  }, ["inventory"] = {  } }, ["param2"] = 0, ["y"] = 6, ["param1"] = 85, ["z"] = 9, ["name"] = "lottother:air" }, { ["x"] = 7, ["meta"] = { ["fields"] = {  }, ["inventory"] = {  } }, ["param2"] = 0, ["y"] = 6, ["param1"] = 102, ["z"] = 10, ["name"] = "lottother:air" }, { ["x"] = 7, ["meta"] = { ["fields"] = {  }, ["inventory"] = {  } }, ["param2"] = 0, ["y"] = 6, ["param1"] = 119, ["z"] = 11, ["name"] = "lottother:air" }, { ["x"] = 7, ["meta"] = { ["fields"] = {  }, ["inventory"] = {  } }, ["param2"] = 0, ["y"] = 6, ["param1"] = 136, ["z"] = 12, ["name"] = "lottother:air" }, { ["x"] = 7, ["meta"] = { ["fields"] = {  }, ["inventory"] = {  } }, ["param2"] = 0, ["y"] = 6, ["param1"] = 153, ["z"] = 13, ["name"] = "lottother:air" }, { ["x"] = 7, ["meta"] = { ["fields"] = {  }, ["inventory"] = {  } }, ["param2"] = 0, ["y"] = 6, ["param1"] = 170, ["z"] = 14, ["name"] = "lottother:air" }, { ["x"] = 7, ["meta"] = { ["fields"] = {  }, ["inventory"] = {  } }, ["param2"] = 0, ["y"] = 6, ["param1"] = 153, ["z"] = 15, ["name"] = "lottother:air" }, { ["x"] = 7, ["meta"] = { ["fields"] = {  }, ["inventory"] = {  } }, ["param2"] = 0, ["y"] = 6, ["param1"] = 136, ["z"] = 16, ["name"] = "lottother:air" }, { ["x"] = 7, ["meta"] = { ["fields"] = {  }, ["inventory"] = {  } }, ["param2"] = 0, ["y"] = 6, ["param1"] = 119, ["z"] = 17, ["name"] = "lottother:air" }, { ["x"] = 7, ["meta"] = { ["fields"] = {  }, ["inventory"] = {  } }, ["param2"] = 0, ["y"] = 6, ["param1"] = 102, ["z"] = 18, ["name"] = "lottother:air" }, { ["x"] = 7, ["meta"] = { ["fields"] = {  }, ["inventory"] = {  } }, ["param2"] = 0, ["y"] = 6, ["param1"] = 85, ["z"] = 19, ["name"] = "lottother:air" }, { ["x"] = 7, ["meta"] = { ["fields"] = {  }, ["inventory"] = {  } }, ["param2"] = 0, ["y"] = 6, ["param1"] = 0, ["z"] = 20, ["name"] = "lottmapgen:mordor_stone" }, { ["x"] = 7, ["meta"] = { ["fields"] = {  }, ["inventory"] = {  } }, ["param2"] = 0, ["y"] = 7, ["param1"] = 0, ["z"] = 8, ["name"] = "lottmapgen:mordor_stone" }, { ["x"] = 7, ["meta"] = { ["fields"] = {  }, ["inventory"] = {  } }, ["param2"] = 0, ["y"] = 7, ["param1"] = 68, ["z"] = 9, ["name"] = "lottother:air" }, { ["x"] = 7, ["meta"] = { ["fields"] = {  }, ["inventory"] = {  } }, ["param2"] = 0, ["y"] = 7, ["param1"] = 85, ["z"] = 10, ["name"] = "lottother:air" }, { ["x"] = 7, ["meta"] = { ["fields"] = {  }, ["inventory"] = {  } }, ["param2"] = 0, ["y"] = 7, ["param1"] = 102, ["z"] = 11, ["name"] = "lottother:air" }, { ["x"] = 7, ["meta"] = { ["fields"] = {  }, ["inventory"] = {  } }, ["param2"] = 0, ["y"] = 7, ["param1"] = 119, ["z"] = 12, ["name"] = "lottother:air" }, { ["x"] = 7, ["meta"] = { ["fields"] = {  }, ["inventory"] = {  } }, ["param2"] = 0, ["y"] = 7, ["param1"] = 136, ["z"] = 13, ["name"] = "lottother:air" }, { ["x"] = 7, ["meta"] = { ["fields"] = {  }, ["inventory"] = {  } }, ["param2"] = 0, ["y"] = 7, ["param1"] = 153, ["z"] = 14, ["name"] = "lottother:air" }, { ["x"] = 7, ["meta"] = { ["fields"] = {  }, ["inventory"] = {  } }, ["param2"] = 0, ["y"] = 7, ["param1"] = 136, ["z"] = 15, ["name"] = "lottother:air" }, { ["x"] = 7, ["meta"] = { ["fields"] = {  }, ["inventory"] = {  } }, ["param2"] = 0, ["y"] = 7, ["param1"] = 119, ["z"] = 16, ["name"] = "lottother:air" }, { ["x"] = 7, ["meta"] = { ["fields"] = {  }, ["inventory"] = {  } }, ["param2"] = 0, ["y"] = 7, ["param1"] = 102, ["z"] = 17, ["name"] = "lottother:air" }, { ["x"] = 7, ["meta"] = { ["fields"] = {  }, ["inventory"] = {  } }, ["param2"] = 0, ["y"] = 7, ["param1"] = 119, ["z"] = 18, ["name"] = "lottother:air" }, { ["x"] = 7, ["meta"] = { ["fields"] = {  }, ["inventory"] = {  } }, ["param2"] = 0, ["y"] = 7, ["param1"] = 102, ["z"] = 19, ["name"] = "lottother:air" }, { ["x"] = 7, ["meta"] = { ["fields"] = {  }, ["inventory"] = {  } }, ["param2"] = 0, ["y"] = 7, ["param1"] = 0, ["z"] = 20, ["name"] = "lottmapgen:mordor_stone" }, { ["x"] = 7, ["meta"] = { ["fields"] = {  }, ["inventory"] = {  } }, ["param2"] = 0, ["y"] = 8, ["param1"] = 0, ["z"] = 8, ["name"] = "lottmapgen:mordor_stone" }, { ["x"] = 7, ["meta"] = { ["fields"] = {  }, ["inventory"] = {  } }, ["param2"] = 0, ["y"] = 8, ["param1"] = 51, ["z"] = 9, ["name"] = "lottother:air" }, { ["x"] = 7, ["meta"] = { ["fields"] = {  }, ["inventory"] = {  } }, ["param2"] = 0, ["y"] = 8, ["param1"] = 68, ["z"] = 10, ["name"] = "lottother:air" }, { ["x"] = 7, ["meta"] = { ["fields"] = {  }, ["inventory"] = {  } }, ["param2"] = 0, ["y"] = 8, ["param1"] = 85, ["z"] = 11, ["name"] = "lottother:air" }, { ["x"] = 7, ["meta"] = { ["fields"] = {  }, ["inventory"] = {  } }, ["param2"] = 0, ["y"] = 8, ["param1"] = 102, ["z"] = 12, ["name"] = "lottother:air" }, { ["x"] = 7, ["meta"] = { ["fields"] = {  }, ["inventory"] = {  } }, ["param2"] = 0, ["y"] = 8, ["param1"] = 119, ["z"] = 13, ["name"] = "lottother:air" }, { ["x"] = 7, ["meta"] = { ["fields"] = {  }, ["inventory"] = {  } }, ["param2"] = 0, ["y"] = 8, ["param1"] = 136, ["z"] = 14, ["name"] = "lottother:air" }, { ["x"] = 7, ["meta"] = { ["fields"] = {  }, ["inventory"] = {  } }, ["param2"] = 0, ["y"] = 8, ["param1"] = 119, ["z"] = 15, ["name"] = "lottother:air" }, { ["x"] = 7, ["meta"] = { ["fields"] = {  }, ["inventory"] = {  } }, ["param2"] = 0, ["y"] = 8, ["param1"] = 102, ["z"] = 16, ["name"] = "lottother:air" }, { ["x"] = 7, ["meta"] = { ["fields"] = {  }, ["inventory"] = {  } }, ["param2"] = 0, ["y"] = 8, ["param1"] = 85, ["z"] = 17, ["name"] = "lottother:air" }, { ["x"] = 7, ["meta"] = { ["fields"] = {  }, ["inventory"] = {  } }, ["param2"] = 0, ["y"] = 8, ["param1"] = 102, ["z"] = 18, ["name"] = "lottother:air" }, { ["x"] = 7, ["meta"] = { ["fields"] = {  }, ["inventory"] = {  } }, ["param2"] = 0, ["y"] = 8, ["param1"] = 85, ["z"] = 19, ["name"] = "lottother:air" }, { ["x"] = 7, ["meta"] = { ["fields"] = {  }, ["inventory"] = {  } }, ["param2"] = 0, ["y"] = 8, ["param1"] = 0, ["z"] = 20, ["name"] = "lottmapgen:mordor_stone" }, { ["x"] = 7, ["meta"] = { ["fields"] = {  }, ["inventory"] = {  } }, ["param2"] = 0, ["y"] = 9, ["param1"] = 0, ["z"] = 8, ["name"] = "lottmapgen:mordor_stone" }, { ["x"] = 7, ["meta"] = { ["fields"] = {  }, ["inventory"] = {  } }, ["param2"] = 0, ["y"] = 9, ["param1"] = 34, ["z"] = 9, ["name"] = "lottother:air" }, { ["x"] = 7, ["meta"] = { ["fields"] = {  }, ["inventory"] = {  } }, ["param2"] = 0, ["y"] = 9, ["param1"] = 51, ["z"] = 10, ["name"] = "lottother:air" }, { ["x"] = 7, ["meta"] = { ["fields"] = {  }, ["inventory"] = {  } }, ["param2"] = 0, ["y"] = 9, ["param1"] = 68, ["z"] = 11, ["name"] = "lottother:air" }, { ["x"] = 7, ["meta"] = { ["fields"] = {  }, ["inventory"] = {  } }, ["param2"] = 0, ["y"] = 9, ["param1"] = 85, ["z"] = 12, ["name"] = "lottother:air" }, { ["x"] = 7, ["meta"] = { ["fields"] = {  }, ["inventory"] = {  } }, ["param2"] = 0, ["y"] = 9, ["param1"] = 102, ["z"] = 13, ["name"] = "lottother:air" }, { ["x"] = 7, ["meta"] = { ["fields"] = {  }, ["inventory"] = {  } }, ["param2"] = 0, ["y"] = 9, ["param1"] = 119, ["z"] = 14, ["name"] = "lottother:air" }, { ["x"] = 7, ["meta"] = { ["fields"] = {  }, ["inventory"] = {  } }, ["param2"] = 0, ["y"] = 9, ["param1"] = 102, ["z"] = 15, ["name"] = "lottother:air" }, { ["x"] = 7, ["meta"] = { ["fields"] = {  }, ["inventory"] = {  } }, ["param2"] = 0, ["y"] = 9, ["param1"] = 85, ["z"] = 16, ["name"] = "lottother:air" }, { ["x"] = 7, ["meta"] = { ["fields"] = {  }, ["inventory"] = {  } }, ["param2"] = 0, ["y"] = 9, ["param1"] = 68, ["z"] = 17, ["name"] = "lottother:air" }, { ["x"] = 7, ["meta"] = { ["fields"] = {  }, ["inventory"] = {  } }, ["param2"] = 0, ["y"] = 9, ["param1"] = 85, ["z"] = 18, ["name"] = "lottother:air" }, { ["x"] = 7, ["meta"] = { ["fields"] = {  }, ["inventory"] = {  } }, ["param2"] = 0, ["y"] = 9, ["param1"] = 68, ["z"] = 19, ["name"] = "lottother:air" }, { ["x"] = 7, ["meta"] = { ["fields"] = {  }, ["inventory"] = {  } }, ["param2"] = 0, ["y"] = 9, ["param1"] = 0, ["z"] = 20, ["name"] = "lottmapgen:mordor_stone" }, { ["x"] = 7, ["meta"] = { ["fields"] = {  }, ["inventory"] = {  } }, ["param2"] = 0, ["y"] = 10, ["param1"] = 0, ["z"] = 8, ["name"] = "lottmapgen:mordor_stone" }, { ["x"] = 7, ["meta"] = { ["fields"] = {  }, ["inventory"] = {  } }, ["param2"] = 0, ["y"] = 10, ["param1"] = 17, ["z"] = 9, ["name"] = "lottother:air" }, { ["x"] = 7, ["meta"] = { ["fields"] = {  }, ["inventory"] = {  } }, ["param2"] = 0, ["y"] = 10, ["param1"] = 34, ["z"] = 10, ["name"] = "lottother:air" }, { ["x"] = 7, ["meta"] = { ["fields"] = {  }, ["inventory"] = {  } }, ["param2"] = 0, ["y"] = 10, ["param1"] = 51, ["z"] = 11, ["name"] = "lottother:air" }, { ["x"] = 7, ["meta"] = { ["fields"] = {  }, ["inventory"] = {  } }, ["param2"] = 0, ["y"] = 10, ["param1"] = 68, ["z"] = 12, ["name"] = "lottother:air" }, { ["x"] = 7, ["meta"] = { ["fields"] = {  }, ["inventory"] = {  } }, ["param2"] = 0, ["y"] = 10, ["param1"] = 85, ["z"] = 13, ["name"] = "lottother:air" }, { ["x"] = 7, ["meta"] = { ["fields"] = {  }, ["inventory"] = {  } }, ["param2"] = 0, ["y"] = 10, ["param1"] = 102, ["z"] = 14, ["name"] = "lottother:air" }, { ["x"] = 7, ["meta"] = { ["fields"] = {  }, ["inventory"] = {  } }, ["param2"] = 0, ["y"] = 10, ["param1"] = 85, ["z"] = 15, ["name"] = "lottother:air" }, { ["x"] = 7, ["meta"] = { ["fields"] = {  }, ["inventory"] = {  } }, ["param2"] = 0, ["y"] = 10, ["param1"] = 68, ["z"] = 16, ["name"] = "lottother:air" }, { ["x"] = 7, ["meta"] = { ["fields"] = {  }, ["inventory"] = {  } }, ["param2"] = 0, ["y"] = 10, ["param1"] = 51, ["z"] = 17, ["name"] = "lottother:air" }, { ["x"] = 7, ["meta"] = { ["fields"] = {  }, ["inventory"] = {  } }, ["param2"] = 0, ["y"] = 10, ["param1"] = 68, ["z"] = 18, ["name"] = "lottother:air" }, { ["x"] = 7, ["meta"] = { ["fields"] = {  }, ["inventory"] = {  } },